Workbook

Sheet Conceptos técnicos
B2: PALABRA | D2: CONCEPTO TÉCNICO | H2: ESTADISTICAS
B3: HTML | D3: El Lenguaje de Marcado de Hipertexto (HTML) es el código que se utiliza para estructurar y desplegar una página web y sus contenidos. Por ejemplo, sus contenidos podrían ser párrafos, una lista con viñetas, o imágenes y tablas de datos. | G3: Requerimientos | H3: Funcionales | I3: =COUNT('Funcionales generales'!B12:D99,'Funcionales DB'!B12:D99,'Funcionales synkro'!B12:B149,'Funcionales Home'!B12:B100,'Funcionales Shop'!B13:B100,'Funcionales Producto'!B13:B100,'Funcionales Carrito'!B13:B100,'Funcionales Checkout'!B13:B100,'Funcionales Ordenes'!B13:B100,'Funcionales Favoritos'!B13:B100,'Funcionales Dashboard Admin'!B13:B100,'Funcionales Gestión Productos'!B12:B100,'Funcionales Gestión Categorías'!B12:B100,'Funcionales Gestión Usuarios'!B12:B100,'Funcionales Gestión Descuentos'!B12:B100,'Funcionales Autenticación'!B12:B100,'Funcionales Pasarela de Pago'!B12:B100,'Funcionales Notificaciones'!B12:B100) -> 208
B4: CSS | D4: Hojas de Estilo en Cascada (del inglés Cascading Style Sheets) o CSS es el lenguaje de estilos utilizado para describir la presentación de documentos HTML o XML (en-US) (incluyendo varios lenguajes basados en XML como SVG, MathML o XHTML). | H4: No Funcionales | I4: =COUNT('No funcionales generales'!B12:D148,'No funcionales DB'!B12:D99,'No funcionales synkro'!B12:D147,'No Funcionales Home'!B12:B100,'No Funcionales Shop'!B13:B100,'No Funcionales Producto'!B13:B100,'No Funcionales Carrito'!B13:B100,'No Funcionales Checkout '!B13:B100,'No Funcionales Ordenes'!B13:B100,'No Funcionales Favoritos'!B13:B100,'No Funcionales Dashboard Admin'!B13:B100,'NoFuncionales Gestión Productos'!B12:B100,'No Funcional Gestión Categoria'!B12:B100,'No Funcionales Gestión Descuen'!B12:B100,'No Funcionales Autenticación'!B12:B100) -> 224
B5: JavaScript | D5: JavaScript es un lenguaje de programación o de secuencias de comandos que te permite implementar funciones complejas en páginas web, cada vez que una página web hace algo más que sentarse allí y mostrar información estática para que la veas, muestra oportunas actualizaciones de contenido, mapas interactivos, animación de Gráficos 2D/3D, desplazamiento de máquinas reproductoras de vídeo, etc., puedes apostar que probablemente JavaScript está involucrado. | H5: TOTALES | I5: =COUNT('No funcionales generales'!B12:D148,'Funcionales generales'!B12:D99,'No funcionales DB'!B12:D99,'Funcionales DB'!B12:D99,'No funcionales synkro'!B12:D147,'Funcionales synkro'!B12:B149,'Funcionales Home'!B12:B100,'No Funcionales Home'!B12:B100,'Funcionales Shop'!B13:B100,'No Funcionales Shop'!B13:B100,'Funcionales Producto'!B13:B100,'No Funcionales Producto'!B13:B100,'Funcionales Carrito'!B13:B100,'No Funcionales Carrito'!B13:B100,'Funcionales Checkout'!B13:B100,'No Funcionales Checkout '!B13:B100,'Funcionales Ordenes'!B13:B100,'No Funcionales Ordenes'!B13:B100,'Funcionales Favoritos'!B13:B100,'No Funcionales Favoritos'!B13:B100,'Funcionales Dashboard Admin'!B13:B100,'No Funcionales Dashboard Admin'!B13:B100,'Funcionales Gestión Productos'!B12:B100,'NoFuncionales Gestión Productos'!B12:B100,'Funcionales Gestión Categorías'!B12:B100,'No Funcional Gestión Categoria'!B12:B100,'Funcionales Gestión Usuarios'!B12:B100,'Funcionales Gestión Descuentos'!B12:B100,'No Funcionales Gestión Descuen'!B12:B100,'Funcionales Autenticación'!B12:B100,'No Funcionales Autenticación'!B12:B100,'Funcionales Pasarela de Pago'!B12:B100,'Funcionales Notificaciones'!B12:B100) -> 432
B6: VISTA | D6: En el desarrollo web, una vista puede ser una página web, pero también puede ser cualquier tipo de componente de la interfaz de usuario, como un encabezado, un pie de página, un formulario, etc. | H6: Cumplidos | I6: =COUNTIF('No funcionales generales'!F12:F144,"x")+COUNTIF('Funcionales generales'!F149,"x")+COUNTIF('No funcionales DB'!F12:F99,"x")+COUNTIF('Funcionales DB'!F12:F99,"x")+COUNTIF('No funcionales synkro'!F12:F97,"x")+COUNTIF('Funcionales synkro'!F12:F99,"x")+COUNTIF('Funcionales Home'!F12:F50,"x")+COUNTIF('No Funcionales Home'!F12:F100,"x")+COUNTIF('Funcionales Shop'!F12:F100,"x")+COUNTIF('No Funcionales Shop'!F12:F100,"x")+COUNTIF('Funcionales Producto'!F12:F100,"x")+COUNTIF('No Funcionales Producto'!F12:F100,"x")+COUNTIF('Funcionales Carrito'!F12:F100,"x")+COUNTIF('No Funcionales Carrito'!F12:F100,"x")+COUNTIF('Funcionales Checkout'!F12:F100,"x")+COUNTIF('No Funcionales Checkout '!F12:F100,"x")+COUNTIF('Funcionales Ordenes'!F12:F100,"x")+COUNTIF('No Funcionales Ordenes'!F12:F100,"x")+COUNTIF('Funcionales Favoritos'!F12:F100,"x")+COUNTIF('No Funcionales Favoritos'!F12:F100,"x")+COUNTIF('Funcionales Dashboard Admin'!F12:F100,"x")+COUNTIF('No Funcionales Dashboard Admin'!F12:F100,"x")+COUNTIF('Funcionales Gestión Productos'!F12:F100,"x")+COUNTIF('NoFuncionales Gestión Productos'!F12:F100,"x")+COUNTIF('Funcionales Gestión Categorías'!F12:F100,"x")+COUNTIF('No Funcional Gestión Categoria'!F12:F100,"x")+COUNTIF('Funcionales Gestión Usuarios'!F12:F100,"x")+COUNTIF('Funcionales Gestión Descuentos'!F12:F100,"x")+COUNTIF('No Funcionales Gestión Descuen'!F12:F100,"x")+COUNTIF('Funcionales Autenticación'!F12:F100,"x")+COUNTIF('No Funcionales Autenticación'!F12:F100,"x")+COUNTIF('Funcionales Pasarela de Pago'!F12:F100,"x")+COUNTIF('Funcionales Notificaciones'!F12:F100,"x") -> 138
B7: React | D7: Es una biblioteca Javascript de código abierto diseñada para crear interfaces de usuario con el objetivo de facilitar el desarrollo de aplicaciones en una sola página. | H7: Porcentaje de cumplimiento | I7: =_xlfn.PERCENTOF(I6,I5) -> 0.31944444
B8: TypeScript | D8: Es un lenguaje de programación de código abierto, creado por Microsoft, que se basa en JavaScript y añade tipos estáticos y otras características para mejorar la seguridad y la escalabilidad en el desarrollo web y de aplicaciones.
B9: Nextjs | D9: Es un framework JavaScript ligero y de código abierto creado sobre React, que permite desarrollar aplicaciones y sitios web muy rápidos y fáciles de usar.
B10: Python | D10: Python es un lenguaje de programación potente y fácil de aprender. Tiene estructuras de datos de alto nivel eficientes y un simple pero efectivo sistema de programación orientado a objetos.
B11: FastAPI | D11: FastAPI es un framework web moderno, rápido (de alto rendimiento), para construir APIs con Python basado en las anotaciones de tipos estándar de Python.
B12: PostgreSQL | D12: Sistema de gestión de bases de datos relacionales de código abierto
B13: Tailwind CSS | D13: Framework de CSS utilitario para diseño rápido y responsivo
B14: JWT | D14: JSON Web Token para autenticación y autorización segura
B15: Pydantic | D15: Biblioteca Python para validación de datos usando anotaciones de tipos
B16: API REST | D16: Arquitectura para servicios web que utiliza métodos HTTP estándar
B17: Middleware | D17: Software que actúa como puente entre diferentes aplicaciones o servicios
B18: CORS | D18: Cross-Origin Resource Sharing para permitir solicitudes entre dominios
B19: Shadcn/ui | D19: Biblioteca de componentes UI reutilizables para React
... B21: CRUD | D21: CRUD es un conjunto de operaciones básicas que se pueden hacer con los datos: crear, leer, actualizar y eliminar información.
B22: Docker
B23: Load balancing
B24: Swagger
B25: OpenAPI
B26: HTTP
B27: HTTPS
B28: Bcrypt
B29: DDoS
B30: Cookies
B31: Normativas de datos GDPR
B32: Normativas de datos GDPR
B33: Lazy Loading
... B41: Notifiaciones TOAST

Sheet Funcionales generales
B2: LISTADO DE REQUERIMIENTOS DE SYNKRO | K2: ESTADISTICAS
K3: Requirimientos | L3: =COUNT(B12:D99) -> 14
B4: SI | C4: Marque con una equis (X) si el sistema cumple con la función descrita | K4: Cumplidos | L4: =COUNTIF(F12:F99,"X") -> 0
B5: NO | C5: Marque con una equis (X) si el sistema no cumple con la función descrita
B6: ADI | C6: Marque con una equis (X) si el sistema debe adicionar la función descrita | K6: Porcentaje | L6: =_xlfn.PERCENTOF(L4,L3) -> 0
B7: Observaciones: | D7: Espacio para complementar respuestas
F9: Nivel de cumplimiento | I9: OBSERVACIONES
B10: REQUISITOS FUNCIONALES GENERALES | F10: SI | G10: NO | H10: ADI
B12: 1 | C12: El sistema debe garantizar la seguridad de los datos almacenados mediante encriptación de contraseñas, autenticación basada en JWT y control de acceso por roles (admin, usuario) | H12: X
B13: 2 | C13: El sistema debe permitir el manejo de datos personales por medio de cookies | H13: X
B14: 3 | C14: El sistema debe estar disponible 24/7 con un tiempo de actividad mínimo del 99% | H14: X
B15: 4 | C15: El sistema es multiusuario con roles diferenciados (administradores y clientes) | H15: X
B16: 5 | C16: El sistema debe ser compatible con navegadores modernos Chrome, Firefox, Safari, Edge | H16: X
B17: 6 | C17: El sistema debe permitir la encripción de contraseñas | H17: X
B18: 7 | C18: El sistema debe cumplir con normativas de protección de datos GDPR/LGPD | H18: X
B19: 8 | C19: El sistema debe soportar dispositivos móviles y tablets responsivamente | H19: X
B20: 9 | C20: El sistema debe bloquear una cuenta después de 5 intentos fallidos de inicio de sesión | H20: X
B21: 10 | C21: El sistema debe permitir al usuario la elección de planes para el arrendamiento de synkro | H21: X
B22: 11 | C22: El sistema debe permitir gestionar el manejo de back-order | H22: X
B23: 12 | C23: El sistema debe incluir herramientas de accesibilidad | H23: X
... B25: 14 | C25: El modelo de negocio debe permitir la implementación de clientes potenciales | H25: X
H26: X
H27: X
H28: X
H29: X
H30: X
H31: X
H32: X
H33: X
H34: X
H35: X
H36: X
H37: X
... H42: X

Sheet No funcionales generales
B2: LISTADO DE REQUERIMIENTOS DE SYNKRO | K2: ESTADISTICAS
K3: Requirimientos | L3: =COUNT(B12:D94) -> 35
B4: SI | C4: Marque con una equis (X) si el sistema cumple con la función descrita | K4: Cumplidos | L4: =COUNTIF(F12:F94,"X") -> 23
B5: NO | C5: Marque con una equis (X) si el sistema no cumple con la función descrita
B6: ADI | C6: Marque con una equis (X) si el sistema debe adicionar la función descrita | I6: =COUNTIF('No funcionales generales'!F12:F144,"x")+COUNTIF('Funcionales generales'!F149,"x")+COUNTIF('No funcionales DB'!F12:F99,"x")+COUNTIF('Funcionales DB'!F12:F99,"x")+COUNTIF('No funcionales synkro'!F12:F97,"x")+COUNTIF('Funcionales synkro'!F12:F99,"x")+COUNTIF('Funcionales Home'!F12:F50,"x")+COUNTIF('No Funcionales Home'!F12:F100,"x")+COUNTIF('Funcionales Shop'!F12:F100,"x")+COUNTIF('No Funcionales Shop'!F12:F100,"x")+COUNTIF('Funcionales Producto'!F12:F100,"x")+COUNTIF('No Funcionales Producto'!F12:F100,"x")+COUNTIF('Funcionales Carrito'!F12:F100,"x")+COUNTIF('No Funcionales Carrito'!F12:F100,"x")+COUNTIF('Funcionales Checkout'!F12:F100,"x")+COUNTIF('No Funcionales Checkout '!F12:F100,"x")+COUNTIF('Funcionales Ordenes'!F12:F100,"x")+COUNTIF('No Funcionales Ordenes'!F12:F100,"x")+COUNTIF('Funcionales Favoritos'!F12:F100,"x")+COUNTIF('No Funcionales Favoritos'!F12:F100,"x")+COUNTIF('Funcionales Dashboard Admin'!F12:F100,"x")+COUNTIF('No Funcionales Dashboard Admin'!F12:F100,"x")+COUNTIF('Funcionales Gestión Productos'!F12:F100,"x")+COUNTIF('NoFuncionales Gestión Productos'!F12:F100,"x")+COUNTIF('Funcionales Gestión Categorías'!F12:F100,"x")+COUNTIF('No Funcional Gestión Categoria'!F12:F100,"x")+COUNTIF('Funcionales Gestión Usuarios'!F12:F100,"x")+COUNTIF('Funcionales Gestión Descuentos'!F12:F100,"x")+COUNTIF('No Funcionales Gestión Descuen'!F12:F100,"x")+COUNTIF('Funcionales Autenticación'!F12:F100,"x")+COUNTIF('No Funcionales Autenticación'!F12:F100,"x")+COUNTIF('Funcionales Pasarela de Pago'!F12:F100,"x")+COUNTIF('Funcionales Notificaciones'!F12:F100,"x") -> 138 | K6: Porcentaje | L6: =_xlfn.PERCENTOF(L4,L3) -> 0.65714286
B7: Observaciones: | D7: Espacio para complementar respuestas
F9: Nivel de cumplimiento | I9: OBSERVACIONES
B10: REQUISITOS NO FUNCIONALES GENERALES | F10: SI | G10: NO | H10: ADI
B12: 1 | C12: El sistema debe garantizar la seguridad de los datos almacenados mediante encriptación de contraseñas, autenticación basada en JWT y control de acceso por roles (admin, usuario) | F12: X
B13: 2 | C13: El sistema debe validar que todos los datos de entrada (productos, usuarios, proveedores,etc) estén completos mediante esquemas Pydantic y mostrar mensajes de error específicos para campos faltantes o inválidos | F13: X
B14: 3 | C14: El sistema debe ser capaz de escalar horizontalmente para adaptarse al crecimiento de usuarios y productos sin afectar el rendimiento mediante pooling de conexiones y cache | H14: X
B15: 4 | C15: La base de datos PostgreSQL debe permitir respaldos automáticos, gestión de transacciones ACID y optimización de consultas | F15: X
B16: 5 | C16: El sistema debe integrar con servicios externos de pagos (futuro) y notificaciones mediante APIs REST | H16: X
B17: 6 | C17: El sistema debe tener un tiempo máximo de respuesta de 2 segundos para operaciones CRUD de productos, usuarios y proveedores | F17: X
B18: 7 | C18: Los permisos de acceso al sistema podrán ser gestionados solo por usuarios con rol de administrador | F18: X
B19: 8 | C19: El sistema debe tener una disponibilidad del 99.9% mediante deployment con contenedores Docker y load balancing | H19: X
B20: 9 | C20: El sistema debe utilizar PostgreSQL como motor de base de datos con funciones almacenadas para operaciones complejas | F20: X
B21: 10 | C21: El sistema debe contar con documentación API automática generada por FastAPI (Swagger/OpenAPI) y manuales de usuario | F21: X
B22: 11 | C22: El sistema debe procesar al menos 100 transacciones por segundo bajo carga normal | F22: X
B23: 12 | C23: El sistema debe manejar errores de forma centralizada con logging estructurado y códigos de estado HTTP apropiados | F23: X
B24: 13 | C24: El sistema debe mantener sesiones de usuario por 24 horas con renovación automática | H24: X
B25: 14 | C25: El sistema debe encriptar contraseñas usando algoritmos argon2 o similares | F25: X
B26: 15 | C26: El sistema debe implementar rate limiting para prevenir ataques DDoS | H26: X
B27: 16 | C27: La búsqueda de productos debe responder en menos de 300ms | H27: X
B28: 17 | C28: El carrito debe calcular totales en menos de 100ms | H28: X
B29: 18 | C29: Los filtros de productos deben responder en menos de 200ms | F29: X
B30: 19 | C30: El sistema debe implementar lazy loading para mejorar velocidad inicial | H30: X
B31: 20 | C31: Las APIs deben responder en menos de 500ms para operaciones CRUD | F31: X
B32: 21 | C32: El sistema debe cargar cualquier página en menos de 3 segundos | F32: X
B33: 22 | C33: Debe soportar hasta 1 millón de productos en catálogo | F33: X
B34: 23 | C34: Todas las comunicaciones deben usar HTTPS/TLS 1.3 | F34: X
B35: 24 | C35: Implementar CSRF protection en formularios | H35: X
B36: 25 | C36: Validación y sanitización de todas las entradas | F36: X
B37: 26 | C37: Formularios deben validarse en tiempo real | F37: X
B38: 27 | C38: Mensajes de error deben ser claros y accionables | F38: X
B39: 28 | C39: Documentación técnica debe actualizarse automáticamente | F39: X
B40: 29 | C40: Logs estructurados para debugging eficiente | F40: X
B41: 30 | C41: Alertas automáticas para errores críticos
B42: 31 | C42: Política de privacidad actualizada y accesible
B43: 32 | C43: Soporte para formatos de datos estándar (JSON, XML) | F43: X
...

Sheet Funcionales DB
B2: LISTADO DE REQUERIMIENTOS DE SYNKRO | K2: ESTADISTICAS
K3: Requirimientos | L3: =COUNT(B12:D99) -> 1
B4: SI | C4: Marque con una equis (X) si el sistema cumple con la función descrita | K4: Cumplidos | L4: =COUNTIF(F12:F99,"X") -> 1
B5: NO | C5: Marque con una equis (X) si el sistema no cumple con la función descrita
B6: ADI | C6: Marque con una equis (X) si el sistema debe adicionar la función descrita | K6: Porcentaje | L6: =_xlfn.PERCENTOF(L4,L3) -> 1
B7: Observaciones: | D7: Espacio para complementar respuestas
F9: Nivel de cumplimiento | I9: OBSERVACIONES
B10: REQUISITOS FUNCIONALES DB | F10: SI | G10: NO | H10: ADI
B12: 1 | C12: El sistema debe tener la capacidad de almacenar datos de manera organizada | F12: X
H13: X
H14: X
H15: X
H16: X
H17: X
H18: X
H19: X
H20: X
H21: X
H22: X
H23: X
H24: X
... H41: X

Sheet No funcionales DB
B2: LISTADO DE REQUERIMIENTOS DE SYNKRO | K2: ESTADISTICAS
K3: Requirimientos | L3: =COUNT(B12:D94) -> 83
B4: SI | C4: Marque con una equis (X) si el sistema cumple con la función descrita | K4: Cumplidos | L4: =COUNTIF(F12:F94,"X") -> 83
B5: NO | C5: Marque con una equis (X) si el sistema no cumple con la función descrita
B6: ADI | C6: Marque con una equis (X) si el sistema debe adicionar la función descrita | K6: Porcentaje | L6: =_xlfn.PERCENTOF(L4,L3) -> 1
B7: Observaciones: | D7: Espacio para complementar respuestas
F9: Nivel de cumplimiento | I9: OBSERVACIONES
B10: REQUISITOS NO FUNCIONALES DB | F10: SI | G10: NO | H10: ADI
B12: 1 | C12: La base de datos del sistema debe permitir integridad relacional | F12: x
B13: 2 | C13: La base de datos del sistema debe estar normalizada teniendo en cuenta las 13 leyes de codd | F13: x
B14: 3 | C14: Las consultas SELECT en `tab_productos` con filtros por categoría, línea y sublínea deben ejecutarse en menos de 200ms para hasta 10,000 productos | F14: x
B15: 4 | C15: La búsqueda por `nom_producto` usando LIKE o full-text search debe retornar resultados en menos de 300ms | F15: x
B16: 5 | C16: La recuperación completa de productos del carrito (`tab_carrito_productos` con JOINs) debe ejecutarse en menos de 150ms. | F16: x
B17: 6 | C17: La inserción de una orden completa en `tab_ordenes` y `tab_orden_productos` debe completarse en menos de 1 segundo. | F17: x
B18: 7 | C18: La actualización de `num_stock` en `tab_productos` y registro en `tab_movimientos_inventario` debe ser atómica y completarse en menos de 100ms. | F18: x
B19: 8 | C19: La consulta de `puntos_disponibles` en `tab_puntos_usuario` debe ejecutarse en menos de 50ms. | F19: x
B20: 9 | C20: La consulta de descuentos aplicables en `tab_descuentos` con todas las validaciones de fechas y condiciones debe ejecutarse en menos de 200ms. | F20: x
B21: 10 | C21: La consulta de historial en `tab_movimientos_puntos` por usuario debe retornar resultados en menos de 300ms para hasta 1000 movimientos. | F21: x
B22: 11 | C22: La consulta en `tab_resumen_ventas_producto` y `tab_resumen_ventas_categoria` debe generar reportes en menos de 2 segundos. | F22: x
B23: 12 | C23: La consulta de productos favoritos en `tab_favoritos` debe ejecutarse en menos de 100ms. | F23: x
... B110: 99 | C110: El catálogo completo de `tab_productos` debe exportarse en formatos estándar. | F110: x

Sheet Funcionales synkro
B2: LISTADO DE REQUERIMIENTOS DE SYNKRO | K2: ESTADISTICAS
K3: Requirimientos | L3: =COUNT(B12:D99) -> 4
B4: SI | C4: Marque con una equis (X) si el sistema cumple con la función descrita | K4: Cumplidos | L4: =COUNTIF(F12:F99,"X") -> 0
B5: NO | C5: Marque con una equis (X) si el sistema no cumple con la función descrita
B6: ADI | C6: Marque con una equis (X) si el sistema debe adicionar la función descrita | K6: Porcentaje | L6: =_xlfn.PERCENTOF(L4,L3) -> 0
B7: Observaciones: | D7: Espacio para complementar respuestas
F9: Nivel de cumplimiento | I9: OBSERVACIONES
B10: REQUISITOS FUNCIONALES SYNKRO | F10: SI | G10: NO | H10: ADI
B12: 1 | C12: El sistema debe mostrar pantallazos del producto en funcionamiento | H12: X
B13: 2 | C13: El sistema debe mostar los diferentes planes que que brrinda synkro (Basic, Pro, Enterprise) | H13: X
B14: 3 | C14: El sistema debe permitir la compra de synkro en base al plan elegido | H14: X
B15: 4 | C15: El sistema debe permitir una pasarela de pagos | H15: X
H16: X
H17: X
H18: X
H19: X
H20: X
H21: X
H22: X
H23: X
H24: X
H25: X
H26: X
H27: X
... H30: X

Sheet No funcionales synkro
B2: LISTADO DE REQUERIMIENTOS DE SYNKRO | K2: ESTADISTICAS
K3: Requirimientos | L3: =COUNT(B12:D28) -> 16
B4: SI | C4: Marque con una equis (X) si el sistema cumple con la función descrita | K4: Cumplidos | L4: =COUNTIF(F12:F28,"X") -> 0
B5: NO | C5: Marque con una equis (X) si el sistema no cumple con la función descrita
B6: ADI | C6: Marque con una equis (X) si el sistema debe adicionar la función descrita | K6: Porcentaje | L6: =_xlfn.PERCENTOF(L4,L3) -> 0
B7: Observaciones: | D7: Espacio para complementar respuestas
F9: Nivel de cumplimiento | I9: OBSERVACIONES
B10: REQUISITOS NO FUNCIONALES SYNKRO | F10: SI | G10: NO | H10: ADI
B12: 1 | C12: La página principal debe cargar completamente en menos de 3 segundos | H12: X
B13: 2 | C13: El slider/banner debe ser responsive y adaptarse a móviles, tablets y desktop | H13: X
B14: 3 | C14: Las imágenes de productos deben optimizarse automáticamente (WebP, compresión) | H14: X
B15: 4 | C15: La interfaz debe mantener contraste mínimo 4.5:1 para accesibilidad WCAG 2.1 | H15: X
B16: 5 | C16: La galería de imágenes debe soportar zoom fluido sin lag perceptible | H16: X
B17: 6 | C17: El formulario de checkout debe validarse en tiempo real con feedback visual | H17: X
B18: 7 | C18: La página debe ser compatible con Chrome, Firefox, Safari, Edge (últimas 2 versiones) | H18: X
B19: 8 | C19: El cambio entre modo claro/oscuro debe ser instantáneo sin parpadeos | H19: X
B20: 9 | C20: Los botones deben tener estados hover, active y disabled claramente diferenciados | H20: X
B21: 10 | C21: La navegación debe ser accesible con teclado (Tab, Enter, Escape) | H21: X
B22: 11 | C22: Las notificaciones toast deben aparecer por máximo 5 segundos | H22: X
B23: 12 | C23: La página debe implementar lazy loading para mejorar velocidad inicial | H23: X
... B27: 16 | C27: Los elementos interactivos deben tener área mínima de 44px para touch | H27: X
H28: X

Sheet Funcionales Home
B2: LISTADO DE REQUERIMIENTOS DE SYNKRO | K2: ESTADISTICAS
K3: Requirimientos | L3: =COUNT(B12:D100) -> 30
B4: SI | C4: Marque con una equis (X) si el sistema cumple con la función descrita | K4: Cumplidos | L4: =COUNTIF(F12:F100,"X") -> 0
B5: NO | C5: Marque con una equis (X) si el sistema no cumple con la función descrita
B6: ADI | C6: Marque con una equis (X) si el sistema debe adicionar la función descrita | K6: Porcentaje | L6: =_xlfn.PERCENTOF(L4,L3) -> 0
B7: Observaciones: | D7: Espacio para complementar respuestas
F9: Nivel de cumplimiento | I9: Observaciones
B10: REQUERIMIENTOS FUNCIONALES DEL HOME | F10: SI | G10: NO | H10: ADI
B12: 1 | C12: El sistema debe mostrar slider principal con navegación automática | H12: X
B13: 2 | C13: El sistema debe mostrar sección "Categories" con 3 categorías principales | H13: X
B14: 3 | C14: El botón "Shop All" debe redirigir a página de tienda completa | H14: X
B15: 4 | C15: Los productos deben mostrar imagen, nombre y precio | H15: X
B16: 5 | C16: Las categorías deben ser clickeables y redirigir a shop filtrado | H16: X
B17: 6 | C17: El slider debe rotar cada 5 segundos automáticamente | H17: X
B18: 7 | C18: El sistema debe mostrar enlaces legales en footer | H18: X
B19: 8 | C19: El sistema debe incluir formulario de newsletter en footer | H19: X
B20: 9 | C20: El sistema debe mostrar slider principal con navegación automática cada 5 segundos | H20: X
B21: 10 | C21: El sistema debe mostrar sección "Categorias" con 3 categorías principales clickeables | H21: X
B22: 11 | C22: El sistema debe mostrar sección "Nuestros Ultimos Productos" con productos recientes | H22: X
B23: 12 | C23: El sistema debe mostrar sección "Nuestros Productos" con productos destacados | H23: X
... B40: 29 | C40: La página debe mostrar una landing de la(s) empresa(s) | H40: X
B41: 30 | C41: El home debe permitir que el admin personalice información de la landing (futuro) | G41: X

Sheet No Funcionales Home
B2: LISTADO DE REQUERIMIENTOS DE SYNKRO | K2: ESTADISTICAS
K3: Requirimientos | L3: =COUNT(B12:D100) -> 24
B4: SI | C4: Marque con una equis (X) si el sistema cumple con la función descrita | K4: Cumplidos | L4: =COUNTIF(F12:F100,"X") -> 0
B5: NO | C5: Marque con una equis (X) si el sistema no cumple con la función descrita | K5: Porcentaje | L5: =_xlfn.PERCENTOF(L4,L3) -> 0
B6: ADI | C6: Marque con una equis (X) si el sistema debe adicionar la función descrita
B7: Observaciones: | D7: Espacio para complementar respuestas
F9: Nivel de cumplimiento | I9: Observaciones
B10: REQUERIMIENTOS NO FUNCIONALES DEL HOME | F10: SI | G10: NO | H10: ADI
B12: 1 | C12: La página debe cargar en menos de 3 segundos | H12: X
B13: 2 | C13: El slider debe ser responsive en móviles | H13: X
B14: 3 | C14: Las imágenes deben optimizarse automáticamente | H14: X
B15: 4 | C15: La página debe ser accesible con navegación por teclado | H15: X
B16: 5 | C16: El contenido debe cargar progresivamente (lazy loading) | H16: X
B17: 6 | C17: La página principal debe cargar completamente en menos de 3 segundos | H17: X
B18: 7 | C18: El slider/banner debe ser responsive y adaptarse a móviles, tablets y desktop | H18: X
B19: 8 | C19: Las imágenes de productos deben optimizarse automáticamente (WebP, compresión) | H19: X
B20: 9 | C20: La interfaz debe mantener contraste mínimo 4.5:1 para accesibilidad WCAG 2.1 | H20: X
B21: 10 | C21: El grid de productos debe ser responsive (3 columnas para desktop, 2 para tablet, 1 para móvil) | H21: X
B22: 11 | C22: Los filtros de productos deben responder en menos de 500ms | H22: X
B23: 12 | C23: La galería de imágenes debe soportar zoom fluido sin lag perceptible | H23: X
... B35: 24 | C35: Los elementos interactivos deben tener área mínima de 44px para touch | H35: X
H36: X

Sheet Funcionales Shop
B2: LISTADO DE REQUERIMIENTOS DE SYNKRO | K2: ESTADISTICAS
K3: Requirimientos | L3: =COUNT(B12:D100) -> 9
B4: SI | C4: Marque con una equis (X) si el sistema cumple con la función descrita | K4: Cumplidos | L4: =COUNTIF(F12:F100,"X") -> 0
B5: NO | C5: Marque con una equis (X) si el sistema no cumple con la función descrita | K5: Porcentaje | L5: =_xlfn.PERCENTOF(L4,L3) -> 0
B6: ADI | C6: Marque con una equis (X) si el sistema debe adicionar la función descrita
B7: Observaciones: | D7: Espacio para complementar respuestas
F10: Nivel de cumplimiento | I10: Observaciones
B11: REQUERIMIENTOS FUNCIONALES SHOP | F11: SI | G11: NO | H11: ADI
B13: 1 | C13: El sistema debe mostrar grid de productos con imagen,nombre, precio | H13: X
B14: 2 | C14: El sistema debe incluir sidebar con filtros por categoría | H14: X
B15: 3 | C15: El sistema debe permitir filtrar por rango de precios | H15: X
B16: 4 | C16: El sistema debe incluir barra de búsqueda en header | H16: X
B17: 5 | C17: El sistema debe mostrar botón "Cargar más productos" para paginación | H17: X
B18: 6 | C18: Los filtros deben aplicarse en tiempo real sin recargar página | H18: X
B19: 7 | C19: El sistema debe mostrar contador de productos encontrados | H19: X
B20: 8 | C20: Los productos deben ser clickeables para ver detalles | H20: X
B21: 9 | C21: El sistema debe mantener filtros activos en navegación | H21: X

Sheet No Funcionales Shop
B2: LISTADO DE REQUERIMIENTOS DE SYNKRO | K2: ESTADISTICAS
K3: Requirimientos | L3: =COUNT(B12:D100) -> 5
B4: SI | C4: Marque con una equis (X) si el sistema cumple con la función descrita | K4: Cumplidos | L4: =COUNTIF(F12:F100,"X") -> 0
B5: NO | C5: Marque con una equis (X) si el sistema no cumple con la función descrita | K5: Porcentaje | L5: =_xlfn.PERCENTOF(L4,L3) -> 0
B6: ADI | C6: Marque con una equis (X) si el sistema debe adicionar la función descrita
B7: Observaciones: | D7: Espacio para complementar respuestas
F10: Nivel de cumplimiento | I10: Observaciones
B11: REQUERIMIENTOS NO FUNCIONALES SHOP | F11: SI | G11: NO | H11: ADI
B13: 1 | C13: La página debe cargar productos en menos de 2 segundos | G13: X
B14: 2 | C14: Los filtros deben responder en menos de 500ms | G14: X
B15: 3 | C15: El grid debe ser responsive (3 columnas desktop, 2 tablet, 1 móvil) | G15: X
B16: 4 | C16: La búsqueda debe soportar autocompletado | G16: X
B17: 5 | C17: La paginación debe cargar máximo 20 productos por página | G17: X | H17: X

Sheet Funcionales Producto
B2: LISTADO DE REQUERIMIENTOS DE SYNKRO | K2: ESTADISTICAS
K3: Requirimientos | L3: =COUNT(B12:D100) -> 10
B4: SI | C4: Marque con una equis (X) si el sistema cumple con la función descrita | K4: Cumplidos | L4: =COUNTIF(F12:F100,"X") -> 0
B5: NO | C5: Marque con una equis (X) si el sistema no cumple con la función descrita | K5: Porcentaje | L5: =_xlfn.PERCENTOF(L4,L3) -> 0
B6: ADI | C6: Marque con una equis (X) si el sistema debe adicionar la función descrita
B7: Observaciones: | D7: Espacio para complementar respuestas
F10: Nivel de cumplimiento | I10: Observaciones
B11: REQUERIMIENTOS FUNCIONALES PRODUCT | F11: SI | G11: NO | H11: ADI
B13: 1 | C13: El sistema debe mostrar galería de imágenes del producto | H13: X
B14: 2 | C14: El sistema debe mostrar nombre del producto como título principal | H14: X
B15: 3 | C15: El sistema debe mostrar precio del producto destacado | H15: X
B16: 4 | C16: El sistema debe incluir descripción detallada del producto | H16: X
B17: 5 | C17: El sistema debe mostrar selector de cantidad con botones +/- | H17: X
B18: 6 | C18: El sistema debe incluir botón "Agregar al carrito" principal | H18: X
B19: 7 | C19: El sistema debe incluir botón de favoritos (corazón) | H19: X
B20: 8 | C20: El sistema debe mostrar formulario newsletter en footer | H20: X
B21: 9 | C21: El sistema debe validar stock disponible antes de agregar al carrito | H21: X
B22: 10 | C22: Las imágenes deben permitir zoom al hacer hover F | H22: X

Sheet No Funcionales Producto
B2: LISTADO DE REQUERIMIENTOS DE SYNKRO | K2: ESTADISTICAS
K3: Requirimientos | L3: =COUNT(B12:D100) -> 5
B4: SI | C4: Marque con una equis (X) si el sistema cumple con la función descrita | K4: Cumplidos | L4: =COUNTIF(F12:F100,"X") -> 0
B5: NO | C5: Marque con una equis (X) si el sistema no cumple con la función descrita | K5: Porcentaje | L5: =_xlfn.PERCENTOF(L4,L3) -> 0
B6: ADI | C6: Marque con una equis (X) si el sistema debe adicionar la función descrita
B7: Observaciones: | D7: Espacio para complementar respuestas
F10: Nivel de cumplimiento | I10: Observaciones
B11: REQUERIMIENTOS NO FUNCIONALES PRODUCT | F11: SI | G11: NO | H11: ADI
B13: 1 | C13: La galería debe cargar imágenes en alta resolución en menos de 1 segundo | H13: X
B14: 2 | C14: El botón "Agregar al Carrito" debe dar feedback visual inmediato | H14: X
B15: 3 | C15: La página debe ser responsive manteniendo usabilidad | H15: X
B16: 4 | C16: Las imágenes deben optimizarse según dispositivo | H16: X
B17: 5 | C17: El selector de cantidad debe validar límites en tiempo real | H17: X

Sheet Funcionales Carrito
B2: LISTADO DE REQUERIMIENTOS DE SYNKRO | K2: ESTADISTICAS
K3: Requirimientos | L3: =COUNT(B12:D100) -> 14
B4: SI | C4: =COUNTIF('No funcionales generales'!F12:F48,"x")+COUNTIF('Funcionales generales'!F12,"x")+COUNTIF('No funcionales synkro'!F12:F28,"x")+COUNTIF('Funcionales synkro'!F12:F30,"x")+COUNTIF('Funcionales Home'!F12:F20,"x")+COUNTIF('No Funcionales Home'!F12:F16,"x")+COUNTIF('Funcionales Shop'!F13:F21,"x")+COUNTIF('No Funcionales Shop'!F13:F17,"x")+COUNTIF('Funcionales Producto'!F13:F22,"x")+COUNTIF('No Funcionales Producto'!F13:F17,"x")+COUNTIF('Funcionales Carrito'!F13:F21,"x")+_xleta.COUNTIF -> #NAME? | K4: Cumplidos | L4: =COUNTIF(F12:F100,"X") -> 0
B5: NO | C5: Marque con una equis (X) si el sistema no cumple con la función descrita | K5: Porcentaje | L5: =_xlfn.PERCENTOF(L4,L3) -> 0
B6: ADI | C6: Marque con una equis (X) si el sistema debe adicionar la función descrita
B7: Observaciones: | D7: Espacio para complementar respuestas
F10: Nivel de cumplimiento | I10: Observaciones
B11: REQUERIMIENTOS FUNCIONALES CARRITO | F11: SI | G11: NO | H11: ADI
B13: 1 | C13: El sistema debe mostrar título "Tu carrito" en header | G13: X
B14: 2 | C14: El sistema debe mostrar productos agregados con imagen y detalles | G14: X
B15: 3 | C15: El sistema debe mostrar precio individual y subtotal por producto | G15: X
B16: 4 | C16: El sistema debe incluir selector de cantidad por producto | G16: X
B17: 5 | C17: El sistema debe mostrar "Resumen del pedido" con totales | G17: X
B18: 6 | C18: El sistema debe incluir campos de información de envío | G18: X
B19: 7 | C19: El sistema debe permitir eliminar productos del carrito | G19: X
B20: 8 | C20: El sistema debe calcular totales automáticamente al cambiar cantidades | G20: X
B21: 9 | C21: El sistema debe validar stock antes de actualizar cantidades | G21: X
B22: 10 | C22: El carrito debe mantener persistencia por 30 días para usuarios no registrados
B23: 11
B24: 12
B25: 13
B26: 14

Sheet No Funcionales Carrito
B2: LISTADO DE REQUERIMIENTOS DE SYNKRO | K2: ESTADISTICAS
K3: Requirimientos | L3: =COUNT(B12:D100) -> 5
B4: SI | C4: Marque con una equis (X) si el sistema cumple con la función descrita | K4: Cumplidos | L4: =COUNTIF(F12:F100,"X") -> 0
B5: NO | C5: Marque con una equis (X) si el sistema no cumple con la función descrita | K5: Porcentaje | L5: =_xlfn.PERCENTOF(L4,L3) -> 0
B6: ADI | C6: Marque con una equis (X) si el sistema debe adicionar la función descrita
B7: Observaciones: | D7: Espacio para complementar respuestas
F10: Nivel de cumplimiento | I10: Observaciones
B11: REQUERIMIENTOS NO FUNCIONALES CARRITO | F11: SI | G11: NO | H11: ADI
B13: 1 | C13: Los cálculos deben actualizarse en tiempo real (menos de 200ms) | G13: X
B14: 2 | C14: El carrito debe persistir por 30 días para usuarios no registrados | G14: X
B15: 3 | C15: El carrito debe sincronizarse entre dispositivos para usuarios logueados | G15: X
B16: 4 | C16: La página debe ser responsive manteniendo funcionalidad completa | G16: X
B17: 5 | C17: Los campos de envío deben validarse en tiempo real | G17: X

Sheet Funcionales Checkout
B2: LISTADO DE REQUERIMIENTOS DE SYNKRO | K2: ESTADISTICAS
K3: Requirimientos | L3: =COUNT(B12:D100) -> 9
B4: SI | C4: Marque con una equis (X) si el sistema cumple con la función descrita | K4: Cumplidos | L4: =COUNTIF(F12:F100,"X") -> 0
B5: NO | C5: Marque con una equis (X) si el sistema no cumple con la función descrita | K5: Porcentaje | L5: =_xlfn.PERCENTOF(L4,L3) -> 0
B6: ADI | C6: Marque con una equis (X) si el sistema debe adicionar la función descrita
B7: Observaciones: | D7: Espacio para complementar respuestas
F10: Nivel de cumplimiento | I10: Observaciones
B11: REQUERIMIENTOS FUNCIONALES CHECKOUT | F11: SI | G11: NO | H11: ADI
B13: 1 | C13: El sistema debe mostrar título "Checkout" en header | G13: X
B14: 2 | C14: El sistema debe mostrar resumen de productos en sidebar | G14: X
B15: 3 | C15: El sistema debe incluir formulario de información personal | G15: X
B16: 4 | C16: El sistema debe incluir sección de información de pago | G16: X
B17: 5 | C17: El sistema debe mostrar total de la orden destacado | G17: X
B18: 6 | C18: El sistema debe incluir botón "Realizar pedido" principal | G18: X
B19: 7 | C19: El sistema debe validar todos los campos antes de procesar | G19: X
B20: 8 | C20: El sistema debe integrar pasarela de pago segura | G20: X
B21: 9 | C21: El sistema debe generar confirmación de orden exitosa | G21: X

Sheet No Funcionales Checkout 
B2: LISTADO DE REQUERIMIENTOS DE SYNKRO | K2: ESTADISTICAS
K3: Requirimientos | L3: =COUNT(B12:D100) -> 5
B4: SI | C4: Marque con una equis (X) si el sistema cumple con la función descrita | K4: Cumplidos | L4: =COUNTIF(F12:F100,"X") -> 1
B5: NO | C5: Marque con una equis (X) si el sistema no cumple con la función descrita | K5: Porcentaje | L5: =_xlfn.PERCENTOF(L4,L3) -> 0.2
B6: ADI | C6: Marque con una equis (X) si el sistema debe adicionar la función descrita
B7: Observaciones: | D7: Espacio para complementar respuestas
F10: Nivel de cumplimiento | I10: Observaciones
B11: REQUERIMIENTOS NO FUNCIONALES CHECKOUT | F11: SI | G11: NO | H11: ADI
B13: 1 | C13: El procesamiento de pago debe completarse en menos de 10 segundos | F13: X
B14: 2 | C14: Los datos de pago deben encriptarse con estándares PCI DSS | G14: X
B15: 3 | C15: El formulario debe ser accesible con navegación por teclado | G15: X
B16: 4 | C16: La validación debe ser en tiempo real con feedback visual | G16: X
B17: 5 | C17: El checkout debe funcionar en modo responsive | G17: X

Sheet Funcionales Ordenes
B2: LISTADO DE REQUERIMIENTOS DE SYNKRO | K2: ESTADISTICAS
K3: Requirimientos | L3: =COUNT(B12:D100) -> 8
B4: SI | C4: Marque con una equis (X) si el sistema cumple con la función descrita | K4: Cumplidos | L4: =COUNTIF(F12:F100,"X") -> 0
B5: NO | C5: Marque con una equis (X) si el sistema no cumple con la función descrita | K5: Porcentaje | L5: =_xlfn.PERCENTOF(L4,L3) -> 0
B6: ADI | C6: Marque con una equis (X) si el sistema debe adicionar la función descrita
B7: Observaciones: | D7: Espacio para complementar respuestas
F10: Nivel de cumplimiento | I10: Observaciones
B11: REQUERIMIENTOS FUNCIONALES ORDENES | F11: SI | G11: NO | H11: ADI
B13: 1 | C13: El sistema debe mostrar título "Mis Ordenes" en header | H13: X
B14: 2 | C14: El sistema debe mostrar columnas: Orden, Fecha, Status, Total, Acciones | H14: X
B15: 3 | C15: El sistema debe mostrar tabla con historial de órdenes | H15: X
B16: 4 | C16: El sistema debe permitir filtrar órdenes por estado | H16: X
B17: 5 | C17: El sistema debe incluir acciones por orden (Ver, Cancelar, Reorder) | H17: X
B18: 6 | C18: El sistema debe permitir ver detalle completo de cada orden | H18: X
B19: 7 | C19: El sistema debe mostrar tracking de envío cuando esté disponible | H19: X
B20: 8 | C20: El sistema debe permitir descargar factura en PDF | H20: X

Sheet No Funcionales Ordenes
B2: LISTADO DE REQUERIMIENTOS DE SYNKRO | K2: ESTADISTICAS
K3: Requirimientos | L3: =COUNT(B12:D100) -> 5
B4: SI | C4: Marque con una equis (X) si el sistema cumple con la función descrita | K4: Cumplidos | L4: =COUNTIF(F12:F100,"X") -> 0
B5: NO | C5: Marque con una equis (X) si el sistema no cumple con la función descrita | K5: Porcentaje | L5: =_xlfn.PERCENTOF(L4,L3) -> 0
B6: ADI | C6: Marque con una equis (X) si el sistema debe adicionar la función descrita
B7: Observaciones: | D7: Espacio para complementar respuestas
F10: Nivel de cumplimiento | I10: Observaciones
B11: REQUERIMIENTOS FUNCIONALES ORDENES | F11: SI | G11: NO | H11: ADI
B13: 1 | C13: La tabla debe cargar órdenes en menos de 2 segundos | H13: X
B14: 2 | C14: La paginación debe manejar hasta 1000 órdenes por usuario | H14: X
B15: 3 | C15: Los filtros deben aplicarse instantáneamente | H15: X
B16: 4 | C16: La tabla debe ser responsive con scroll horizontal en móviles | H16: X
B17: 5 | C17: Las acciones deben tener confirmación para evitar errores | H17: X

Sheet Funcionales Favoritos
B2: LISTADO DE REQUERIMIENTOS DE SYNKRO | K2: ESTADISTICAS
K3: Requirimientos | L3: =COUNT(B12:D100) -> 9
B4: SI | C4: Marque con una equis (X) si el sistema cumple con la función descrita | K4: Cumplidos | L4: =COUNTIF(F12:F100,"X") -> 0
B5: NO | C5: Marque con una equis (X) si el sistema no cumple con la función descrita | K5: Porcentaje | L5: =_xlfn.PERCENTOF(L4,L3) -> 0
B6: ADI | C6: Marque con una equis (X) si el sistema debe adicionar la función descrita
B7: Observaciones: | D7: Espacio para complementar respuestas
B9: REQUERIMIENTOS FUNCIONALES DE LA SECRETARIA GESTORA (FUNCIONARIO)
F10: Nivel de cumplimiento | I10: Observaciones
B11: REQUERIMIENTOS FUNCIONALES FAVORITOS | F11: SI | G11: NO | H11: ADI
B13: 1 | C13: El sistema debe mostrar título "Favoritos" en header
B14: 2 | C14: El sistema debe mostrar grid de productos favoritos
B15: 3 | C15: El sistema debe mostrar productos con imagen, nombre, precio
B16: 4 | C16: El sistema debe incluir botón para remover de favoritos
B17: 5 | C17: El sistema debe incluir botón "Agregar al carrito" por producto
B18: 6 | C18: El sistema debe mostrar mensaje cuando lista esté vacía
B19: 7 | C19: El sistema debe sincronizar favoritos entre dispositivos
B20: 8 | C20: El sistema debe notificar cambios de precio en favoritos
B21: 9 | C21: El sistema debe mostrar disponibilidad de stock

Sheet No Funcionales Favoritos
B2: LISTADO DE REQUERIMIENTOS DE SYNKRO | K2: ESTADISTICAS
K3: Requirimientos | L3: =COUNT(B12:D100) -> 5
B4: SI | C4: Marque con una equis (X) si el sistema cumple con la función descrita | K4: Cumplidos | L4: =COUNTIF(F12:F100,"X") -> 0
B5: NO | C5: Marque con una equis (X) si el sistema no cumple con la función descrita | K5: Porcentaje | L5: =_xlfn.PERCENTOF(L4,L3) -> 0
B6: ADI | C6: Marque con una equis (X) si el sistema debe adicionar la función descrita
B7: Observaciones: | D7: Espacio para complementar respuestas
B9: REQUERIMIENTOS FUNCIONALES DE LA SECRETARIA GESTORA (FUNCIONARIO)
F10: Nivel de cumplimiento | I10: Observaciones
B11: REQUERIMIENTOS NO FUNCIONALES FAVORITOS | F11: SI | G11: NO | H11: ADI
B13: 1 | C13: Los favoritos deben cargarse en menos de 1 segundo_x000D_
B14: 2 | C14: La sincronización debe ser en tiempo real
B15: 3 | C15: El grid debe ser responsive (3-2-1 columnas)
B16: 4 | C16: Las acciones deben tener feedback visual inmediato
B17: 5 | C17: La lista debe soportar hasta 500 productos favoritos

Sheet Funcionales Dashboard Admin
B2: LISTADO DE REQUERIMIENTOS DE SYNKRO | K2: ESTADISTICAS
K3: Requirimientos | L3: =COUNT(B12:D100) -> 15
B4: SI | C4: Marque con una equis (X) si el sistema cumple con la función descrita | K4: Cumplidos | L4: =COUNTIF(F12:F100,"X") -> 0
B5: NO | C5: Marque con una equis (X) si el sistema no cumple con la función descrita | K5: Porcentaje | L5: =_xlfn.PERCENTOF(L4,L3) -> 0
B6: ADI | C6: Marque con una equis (X) si el sistema debe adicionar la función descrita
B7: Observaciones: | D7: Espacio para complementar respuestas
B9: REQUERIMIENTOS FUNCIONALES DE LA SECRETARIA GESTORA (FUNCIONARIO)
F10: Nivel de cumplimiento | I10: Observaciones
B11: REQUERIMIENTOS FUNCIONALES DASHBOARD ADMIN | F11: SI | G11: NO | H11: ADI
B13: 1 | C13: El sistema debe mostrar sidebar con navegación principal | H13: X
B14: 2 | C14: El sistema debe mostrar métricas principales en cards superiores | H14: X
B15: 3 | C15: El sistema debe incluir panel de notificaciones lateral | H15: X
B16: 4 | C16: El sistema debe incluir toggle para modo claro/oscuro | H16: X
B17: 5 | C17: El sistema debe mostrar datos en tiempo real | H17: X
B18: 6 | C18: Los gráficos deben ser interactivos con tooltips | H18: X
B19: 7 | C19: El sistema debe permitir filtrar datos por período | H19: X
B20: 8 | C20: El sistema debe mantener toda la funcionalidad en modo oscuro | H20: X
B21: 9 | C21: El sistema debe mantener contraste adecuado en textos | H21: X
B22: 10 | C22: Los gráficos deben adaptarse al tema oscuro | H22: X
B23: 11 | C23: El sistema debe guardar preferencia de tema por usuario | H23: X
B24: 12 | C24: El toggle de tema debe mostrar estado actual claramente | H24: X
... B27: 15 | C27: Cada KPI debe corresponder a una grafica elegíble por el administrador | H27: X

Sheet No Funcionales Dashboard Admin
B2: LISTADO DE REQUERIMIENTOS DE SYNKRO | K2: ESTADISTICAS
K3: Requirimientos | L3: =COUNT(B12:D100) -> 11
B4: SI | C4: Marque con una equis (X) si el sistema cumple con la función descrita | K4: Cumplidos | L4: =COUNTIF(F12:F100,"X") -> 0
B5: NO | C5: Marque con una equis (X) si el sistema no cumple con la función descrita | K5: Porcentaje | L5: =_xlfn.PERCENTOF(L4,L3) -> 0
B6: ADI | C6: Marque con una equis (X) si el sistema debe adicionar la función descrita
B7: Observaciones: | D7: Espacio para complementar respuestas
B9: REQUERIMIENTOS FUNCIONALES DE LA SECRETARIA GESTORA (FUNCIONARIO)
F10: Nivel de cumplimiento | I10: Observaciones
B11: REQUERIMIENTOS FUNCIONALES DASHBOARD ADMIN | F11: SI | G11: NO | H11: ADI
B13: 1 | C13: El dashboard debe cargar en menos de 3 segundos | H13: X
B14: 2 | C14: Los gráficos deben renderizarse en menos de 1 segundo | H14: X
B15: 3 | C15: El dashboard debe ser responsive manteniendo funcionalidad | H15: X
B16: 4 | C16: Los datos deben actualizarse cada 30 segundos automáticamente | H16: X
B17: 5 | C17: El cambio de tema debe ser instantáneo | H17: X
B18: 6 | C18: El cambio de tema debe ser fluido sin parpadeos | H18: X
B19: 7 | C19: El modo oscuro debe cumplir estándares de accesibilidad | H19: X
B20: 8 | C20: Los colores deben mantener jerarquía visual apropiada | H20: X
B21: 9 | C21: El contraste debe ser mínimo 4.5:1 para textos | H21: X
B22: 10 | C22: La preferencia debe persistir entre sesiones | H22: X
B23: 11 | C23: el sistema deber permitir la importación de archivos excel (xlsx, xls, csv) al daschboard | H23: X
H24: X

Sheet Funcionales Gestión Productos
B2: LISTADO DE REQUERIMIENTOS DE SYNKRO | K2: ESTADISTICAS
K3: Requirimientos | L3: =COUNT(B12:D100) -> 10
B4: SI | C4: Marque con una equis (X) si el sistema cumple con la función descrita | K4: Cumplidos | L4: =COUNTIF(F12:F100,"X") -> 4
B5: NO | C5: Marque con una equis (X) si el sistema no cumple con la función descrita | K5: Porcentaje | L5: =_xlfn.PERCENTOF(L4,L3) -> 0.4
B6: ADI | C6: Marque con una equis (X) si el sistema debe adicionar la función descrita
B7: Observaciones: | D7: Espacio para complementar respuestas
F9: Nivel de cumplimiento | I9: Observaciones
B10: REQUIRIMIENTOS FUNCIONALES GESTIÓN PRODUCTOS | F10: SI | G10: NO | H10: ADI
B12: 1 | C12: El sistema debe permitir crear nuevos productos | F12: X
B13: 2 | C13: El sistema debe permitir editar productos existentes | F13: X
B14: 3 | C14: El sistema debe permitir eliminar productos | F14: X
B15: 4 | C15: El sistema debe permitir subir múltiples imágenes
B16: 5 | C16: El sistema debe permitir asignar categorías, líneas, sublíneas | F16: X
B17: 6 | C17: El sistema debe permitir gestionar stock
B18: 7 | C18: El sistema debe permitir configurar precios y descuentos
B19: 8 | C19: El sistema debe permitir activar/desactivar productos
B20: 9 | C20: El sistema debe validar campos obligatorios
B21: 10 | C21: El sistema debe permitir importar productos via CSV

Sheet NoFuncionales Gestión Productos
B2: LISTADO DE REQUERIMIENTOS DE SYNKRO | K2: ESTADISTICAS
K3: Requirimientos | L3: =COUNT(B12:D100) -> 5
B4: SI | C4: Marque con una equis (X) si el sistema cumple con la función descrita | K4: Cumplidos | L4: =COUNTIF(F12:F100,"X") -> 1
B5: NO | C5: Marque con una equis (X) si el sistema no cumple con la función descrita | K5: Porcentaje | L5: =_xlfn.PERCENTOF(L4,L3) -> 0.2
B6: ADI | C6: Marque con una equis (X) si el sistema debe adicionar la función descrita
B7: Observaciones: | D7: Espacio para complementar respuestas
F9: Nivel de cumplimiento | I9: Observaciones
B10: REQUIRIMIENTOS NO FUNCIONALES GESTIÓN PRODUCTOS | F10: SI | G10: NO | H10: ADI
B12: 1 | C12: La carga de imágenes debe completarse en menos de 5 segundos
B13: 2 | C13: El sistema debe soportar imágenes hasta 10MB
B14: 3 | C14: Las imágenes deben optimizarse automáticamente
B15: 4 | C15: El formulario debe validarse en tiempo real | F15: X
B16: 5 | C16: La importación CSV debe procesar hasta 1000 productos

Sheet Funcionales Gestión Categorías
B2: LISTADO DE REQUERIMIENTOS DE SYNKRO | K2: ESTADISTICAS
K3: Requirimientos | L3: =COUNT(B12:D100) -> 10
B4: SI | C4: Marque con una equis (X) si el sistema cumple con la función descrita | K4: Cumplidos | L4: =COUNTIF(F12:F100,"X") -> 5
B5: NO | C5: Marque con una equis (X) si el sistema no cumple con la función descrita | K5: Porcentaje | L5: =_xlfn.PERCENTOF(L4,L3) -> 0.5
B6: ADI | C6: Marque con una equis (X) si el sistema debe adicionar la función descrita
B7: Observaciones: | D7: Espacio para complementar respuestas
F9: Nivel de cumplimiento | I9: Observaciones
B10: REQUIRIMIENTOS FUNCIONALES GESTIÓN CATEGORIAS | F10: SI | G10: NO | H10: ADI
B12: 1 | C12: El sistema debe permitir crear categorías principales | F12: X
B13: 2 | C13: El sistema debe permitir crear líneas dentro de categorías | F13: X
B14: 3 | C14: El sistema debe permitir crear sublíneas dentro de líneas | F14: X
B15: 4 | C15: El sistema debe permitir editar información de categorías | F15: X
B16: 5 | C16: El sistema debe permitir eliminar categorías vacías | F16: X
B17: 6 | C17: El sistema debe permitir asignar imágenes a categorías
B18: 7 | C18: El sistema debe mostrar contador de productos por categoría
B19: 8 | C19: El sistema debe permitir ordenar categorías por prioridad
B20: 9 | C20: El sistema debe validar que no se eliminen categorías con productos
B21: 10 | C21: El sistema debe permitir activar/desactivar categorías

Sheet No Funcional Gestión Categoria
B2: LISTADO DE REQUERIMIENTOS DE SYNKRO | K2: ESTADISTICAS
K3: Requirimientos | L3: =COUNT(B12:D100) -> 5
B4: SI | C4: Marque con una equis (X) si el sistema cumple con la función descrita | K4: Cumplidos | L4: =COUNTIF(F12:F100,"X") -> 0
B5: NO | C5: Marque con una equis (X) si el sistema no cumple con la función descrita | K5: Porcentaje | L5: =_xlfn.PERCENTOF(L4,L3) -> 0
B6: ADI | C6: Marque con una equis (X) si el sistema debe adicionar la función descrita
B7: Observaciones: | D7: Espacio para complementar respuestas
F9: Nivel de cumplimiento | I9: Observaciones
B10: REQUIRIMIENTOS FUNCIONALES GESTIÓN CATEGORIAS | F10: SI | G10: NO | H10: ADI
B12: 1 | C12: La estructura jerárquica debe cargarse en menos de 1 segundo
B13: 2 | C13: El sistema debe soportar hasta 5 niveles de jerarquía
B14: 3 | C14: Los cambios deben reflejarse inmediatamente en frontend
B15: 4 | C15: La validación debe prevenir eliminación accidental
B16: 5 | C16: El ordenamiento debe ser drag-and-drop intuitivo

Sheet Funcionales Gestión Usuarios
B2: LISTADO DE REQUERIMIENTOS DE SYNKRO | K2: ESTADISTICAS
K3: Requirimientos | L3: =COUNT(B12:D100) -> 15
B4: SI | C4: Marque con una equis (X) si el sistema cumple con la función descrita | K4: Cumplidos | L4: =COUNTIF(F12:F100,"X") -> 2
B5: NO | C5: Marque con una equis (X) si el sistema no cumple con la función descrita | K5: Porcentaje | L5: =_xlfn.PERCENTOF(L4,L3) -> 0.13333333
B6: ADI | C6: Marque con una equis (X) si el sistema debe adicionar la función descrita
B7: Observaciones: | D7: Espacio para complementar respuestas
F9: Nivel de cumplimiento | I9: Observaciones
B10: REQUIRIMIENTOS FUNCIONALES GESTIÓN USUARIOS | F10: SI | G10: NO | H10: ADI
B12: 1 | C12: El sistema debe permitir ver lista de todos los usuarios | F12: X
B13: 2 | C13: El sistema debe permitir buscar usuarios por email, nombre
B14: 3 | C14: El sistema debe permitir ver perfil completo de usuarios | F14: X
B15: 4 | C15: El sistema debe permitir editar información de usuarios
B16: 5 | C16: El sistema debe permitir activar/desactivar cuentas de usuario
B17: 6 | C17: El sistema debe permitir asignar roles de administrador
B18: 7 | C18: El sistema debe permitir ver historial de órdenes por usuario
B19: 8 | C19: El sistema debe permitir resetear contraseñas de usuarios
B20: 9 | C20: El sistema debe mostrar estadísticas de actividad por usuario
B21: 10 | C21: El sistema debe permitir enviar emails masivos a usuarios
B22: 11 | C22: El sistema debe permitir exportar lista de usuarios
B23: 12 | C23: El sistema debe mostrar usuarios registrados por período
B24: 13 | C24: El sistema debe permitir filtrar usuarios por estado, rol, fecha
B25: 14 | C25: El sistema debe mostrar valor total de compras por usuario
B26: 15 | C26: El sistema debe permitir crear usuarios administradores

Sheet Funcionales Gestión Descuentos
B2: LISTADO DE REQUERIMIENTOS DE SYNKRO | K2: ESTADISTICAS
K3: Requirimientos | L3: =COUNT(B12:D100) -> 10
B4: SI | C4: Marque con una equis (X) si el sistema cumple con la función descrita | K4: Cumplidos | L4: =COUNTIF(F12:F100,"X") -> 0
B5: NO | C5: Marque con una equis (X) si el sistema no cumple con la función descrita | K5: Porcentaje | L5: =_xlfn.PERCENTOF(L4,L3) -> 0
B6: ADI | C6: Marque con una equis (X) si el sistema debe adicionar la función descrita
B7: Observaciones: | D7: Espacio para complementar respuestas
F9: Nivel de cumplimiento | I9: Observaciones
B10: REQUIRIMIENTOS FUNCIONALES GESTIÓN DESCUENTOS | F10: SI | G10: NO | H10: ADI
B12: 1 | C12: El sistema debe permitir crear códigos de descuento
B13: 2 | C13: El sistema debe configurar porcentaje o monto fijo
B14: 3 | C14: El sistema debe configurar fechas de vigencia
B15: 4 | C15: El sistema debe limitar uso por usuario
B16: 5 | C16: El sistema debe configurar monto mínimo de compra
B17: 6 | C17: El sistema debe aplicar descuentos a categorías específicas
B18: 7 | C18: El sistema debe validar códigos en tiempo real
B19: 8 | C19: El sistema debe mostrar estadísticas de uso
B20: 9 | C20: El sistema debe permitir desactivar códigos
B21: 10 | C21: El sistema debe generar reportes de efectividad

Sheet No Funcionales Gestión Descuen
B2: LISTADO DE REQUERIMIENTOS DE SYNKRO | K2: ESTADISTICAS
K3: Requirimientos | L3: =COUNT(B12:D100) -> 5
B4: SI | C4: Marque con una equis (X) si el sistema cumple con la función descrita | K4: Cumplidos | L4: =COUNTIF(F12:F100,"X") -> 0
B5: NO | C5: Marque con una equis (X) si el sistema no cumple con la función descrita | K5: Porcentaje | L5: =_xlfn.PERCENTOF(L4,L3) -> 0
B6: ADI | C6: Marque con una equis (X) si el sistema debe adicionar la función descrita
B7: Observaciones: | D7: Espacio para complementar respuestas
F9: Nivel de cumplimiento | I9: Observaciones
B10: REQUIRIMIENTOS NO FUNCIONALES GESTIÓN DESCUENTOS | F10: SI | G10: NO | H10: ADI
B12: 1 | C12: La validación de códigos debe ser instantánea
B13: 2 | C13: El sistema debe soportar hasta 10,000 códigos activos
B14: 3 | C14: Los reportes deben generarse en menos de 3 segundos
B15: 4 | C15: Los descuentos deben aplicarse sin afectar rendimiento
B16: 5 | C16: El sistema debe prevenir uso fraudulento de códigos

Sheet Funcionales Autenticación
B2: LISTADO DE REQUERIMIENTOS DE SYNKRO | K2: ESTADISTICAS
K3: Requirimientos | L3: =COUNT(B12:D100) -> 10
B4: SI | C4: Marque con una equis (X) si el sistema cumple con la función descrita | K4: Cumplidos | L4: =COUNTIF(F12:F100,"X") -> 8
B5: NO | C5: Marque con una equis (X) si el sistema no cumple con la función descrita | K5: Porcentaje | L5: =_xlfn.PERCENTOF(L4,L3) -> 0.8
B6: ADI | C6: Marque con una equis (X) si el sistema debe adicionar la función descrita
B7: Observaciones: | D7: Espacio para complementar respuestas
F9: Nivel de cumplimiento | I9: Observaciones
B10: REQUIRIMIENTOS FUNCIONALES AUTENTICACIÓN | F10: SI | G10: NO | H10: ADI
B12: 1 | C12: El sistema debe permitir registro con email y contraseña | F12: X
B13: 2 | C13: El sistema debe validar formato de email en tiempo real | F13: X
B14: 3 | C14: El sistema debe validar fortaleza de contraseña | F14: X
B15: 4 | C15: El sistema debe generar JWT token al iniciar sesión | F15: X
B16: 5 | C16: El sistema debe implementar middleware de autenticación | F16: X
B17: 6 | C17: El sistema debe permitir recuperación de contraseña
B18: 7 | C18: El sistema debe proteger rutas de administrador | F18: X
B19: 8 | C19: El sistema debe cerrar sesión e invalidar tokens | F19: X
B20: 9 | C20: El sistema debe renovar tokens automáticamente | F20: X
B21: 10 | C21: El sistema debe enviar emails de verificación

Sheet No Funcionales Autenticación
B2: LISTADO DE REQUERIMIENTOS DE SYNKRO | K2: ESTADISTICAS
K3: Requirimientos | L3: =COUNT(B12:D100) -> 5
B4: SI | C4: Marque con una equis (X) si el sistema cumple con la función descrita | K4: Cumplidos | L4: =COUNTIF(F12:F100,"X") -> 5
B5: NO | C5: Marque con una equis (X) si el sistema no cumple con la función descrita | K5: Porcentaje | L5: =_xlfn.PERCENTOF(L4,L3) -> 1
B6: ADI | C6: Marque con una equis (X) si el sistema debe adicionar la función descrita
B7: Observaciones: | D7: Espacio para complementar respuestas
F9: Nivel de cumplimiento | I9: Observaciones
B10: REQUIRIMIENTOS FUNCIONALES AUTENTICACIÓN | F10: SI | G10: NO | H10: ADI
B12: 1 | C12: Los tokens JWT deben expirar en 24 horas | F12: X
B13: 2 | C13: Las contraseñas deben encriptarse con bcrypt | F13: X
B14: 3 | C14: El sistema debe implementar rate limiting en auth | F14: X
B15: 4 | C15: Los intentos fallidos deben bloquearse después de 5 intentos | F15: X
B16: 5 | C16: Todas las operaciones de auth deben loggearse | F16: X

Sheet Funcionales Pasarela de Pago
B2: LISTADO DE REQUERIMIENTOS DE SYNKRO | K2: ESTADISTICAS
K3: Requirimientos | L3: =COUNT(B12:D100) -> 15
B4: SI | C4: Marque con una equis (X) si el sistema cumple con la función descrita | K4: Cumplidos | L4: =COUNTIF(F12:F100,"X") -> 0
B5: NO | C5: Marque con una equis (X) si el sistema no cumple con la función descrita | K5: Porcentaje | L5: =_xlfn.PERCENTOF(L4,L3) -> 0
B6: ADI | C6: Marque con una equis (X) si el sistema debe adicionar la función descrita
B7: Observaciones: | D7: Espacio para complementar respuestas
F9: Nivel de cumplimiento | I9: Observaciones
B10: REQUIRIMIENTOS FUNCIONALES PASARELA DE PAGO | F10: SI | G10: NO | H10: ADI
B12: 1 | C12: El sistema debe integrar con múltiples proveedores de pago
B13: 2 | C13: El sistema debe soportar tarjetas de crédito y débito
B14: 3 | C14: El sistema debe soportar PayPal como método de pago
B15: 4 | C15: El sistema debe soportar transferencias bancarias
B16: 5 | C16: El sistema debe validar información de tarjetas en tiempo real
B17: 6 | C17: El sistema debe encriptar información sensible de pago
B18: 7 | C18: El sistema debe manejar respuestas de autorización de pago
B19: 8 | C19: El sistema debe procesar reembolsos automáticamente
B20: 9 | C20: El sistema debe guardar métodos de pago para usuarios registrados
B21: 10 | C21: El sistema debe implementar tokenización de tarjetas
B22: 11 | C22: El sistema debe manejar pagos en múltiples monedas
B23: 12 | C23: El sistema debe implementar verificación 3D Secure
... B26: 15 | C26: El sistema debe manejar pagos fallidos con reintentos

Sheet Funcionales Notificaciones
B2: LISTADO DE REQUERIMIENTOS DE SYNKRO | K2: ESTADISTICAS
K3: Requirimientos | L3: =COUNT(B12:D100) -> 15
B4: SI | C4: Marque con una equis (X) si el sistema cumple con la función descrita | K4: Cumplidos | L4: =COUNTIF(F12:F100,"X") -> 0
B5: NO | C5: Marque con una equis (X) si el sistema no cumple con la función descrita | K5: Porcentaje | L5: =_xlfn.PERCENTOF(L4,L3) -> 0
B6: ADI | C6: Marque con una equis (X) si el sistema debe adicionar la función descrita
B7: Observaciones: | D7: Espacio para complementar respuestas
F9: Nivel de cumplimiento | I9: Observaciones
B10: REQUIRIMIENTOS FUNCIONALES NOTIFICACIONES | F10: SI | G10: NO | H10: ADI
B12: 1 | C12: El sistema debe enviar email de confirmación de registro
B13: 2 | C13: El sistema debe enviar email de confirmación de orden
B14: 3 | C14: El sistema debe enviar notificaciones de cambio de estado de orden
B15: 4 | C15: El sistema debe enviar email de recuperación de contraseña
B16: 5 | C16: El sistema debe enviar notificaciones de productos en oferta
B17: 6 | C17: El sistema debe enviar recordatorios de carrito abandonado
B18: 7 | C18: El sistema debe enviar newsletter a suscriptores
B19: 8 | C19: El sistema debe permitir personalizar plantillas de email
B20: 9 | C20: El sistema debe implementar cola de emails para envío masivo
B21: 10 | C21: El sistema debe permitir desuscripción de emails
B22: 11 | C22: El sistema debe enviar SMS para órdenes importantes (futuro)
B23: 12 | C23: El sistema debe enviar notificaciones push (futuro)
... B26: 15 | C26: El sistema debe implementar preferencias de notificación por usuario
