Workbook

Sheet Indice
A1: Nombre de la Hoja | B1: Categoría | C1: Ubicación | E1: Categoría | F1: (Todas) | T1: Estadisticas
A2: Estadisticas | B2: Otros | C2: Ir a la hoja → | H2: https://compralo.revital.cloud/ | T2: Funcionales generales
A3: Funcionales generales | B3: Funcionales | C3: Ir a la hoja → | E3: Etiquetas de fila | T3: No-funcionales generales
A4: No-funcionales generales | B4: No-funcionales | C4: Ir a la hoja → | E4: Estadisticas | T4: Funcionales DB
A5: Funcionales DB | B5: Funcionales | C5: Ir a la hoja → | E5: Ir a la hoja → | H5: Credenciales Server | T5: No-funcionales DB
A6: No-funcionales DB | B6: No-funcionales | C6: Ir a la hoja → | E6: Funcionales Acerca de | H6: IP: | I6: 46.225.94.64 | T6: Funcionales Homepage
A7: Funcionales Homepage | B7: Funcionales | C7: Ir a la hoja → | E7: Ir a la hoja → | H7: user | I7: tester | T7: No-funcionales Homepage
A8: No-funcionales Homepage | B8: No-funcionales | C8: Ir a la hoja → | E8: Funcionales Atributos | H8: psw | I8: tS!@D26fBQfw*N8 | T8: Funcionales Productos
A9: Funcionales Productos | B9: Funcionales | C9: Ir a la hoja → | E9: Ir a la hoja → | H9: ssh | I9: tester@46.225.94.64 | T9: No-funcionales Productos
A10: No-funcionales Productos | B10: No-funcionales | C10: Ir a la hoja → | E10: Funcionales Ayuda | T10: Funcionales Categoria
A11: Funcionales Categoria | B11: Funcionales | C11: Ir a la hoja → | E11: Ir a la hoja → | H11: Credenciales PGADMIN | T11: No-funcionales Categoria
A12: No-funcionales Categoria | B12: No-funcionales | C12: Ir a la hoja → | E12: Funcionales barra informativa | H12: DB | I12: revital_ecommerce | T12: Funcionales Descuentos
A13: Funcionales Descuentos | B13: Funcionales | C13: Ir a la hoja → | E13: Ir a la hoja → | H13: user | I13: synkro_admin | T13: No-funcionales Descuentos
A14: No-funcionales Descuentos | B14: No-funcionales | C14: Ir a la hoja → | E14: Funcionales Bot-Admin | H14: password | I14: synkro_admin_pwd | T14: Funcionales Cookies
A15: Funcionales Cookies | B15: Funcionales | C15: Ir a la hoja → | E15: Ir a la hoja → | T15: No-funcionales Cookies
A16: No-funcionales Cookies | B16: No-funcionales | C16: Ir a la hoja → | E16: Funcionales Boton Ayuda | H16: Credenciales Software | T16: Funcionales Politicas
A17: Funcionales Politicas | B17: Funcionales | C17: Ir a la hoja → | E17: Ir a la hoja → | G17: Admin | H17: usuario | I17: ahernandezlara03@gmail.com | T17: No-funcionales Politicas
A18: No-funcionales Politicas | B18: No-funcionales | C18: Ir a la hoja → | E18: Funcionales Carrito | H18: contraseña | I18: Alejandro03* | T18: Funcionales Terminos condicione
A19: Funcionales Terminos condicione | B19: Funcionales | C19: Ir a la hoja → | E19: Ir a la hoja → | G19: Usuario | H19: usuario | I19: Debe ser creado | T19: No-funcionales Terminos Condici
A20: No-funcionales Terminos Condici | B20: No-funcionales | C20: Ir a la hoja → | E20: Funcionales Categoria | H20: contraseña | T20: Funcionales Perfil
A21: Funcionales Perfil | B21: Funcionales | C21: Ir a la hoja → | E21: Ir a la hoja → | T21: No-funcionales Perfil
A22: No-funcionales Perfil | B22: No-funcionales | C22: Ir a la hoja → | E22: Funcionales Categorías Admin | H22: Datos de Prueba Pagos Wompi | T22: Funcionales Contacto
A23: Funcionales Contacto | B23: Funcionales | C23: Ir a la hoja → | E23: Ir a la hoja → | H23: Nequi | I23: 3991111111 | T23: No-funcionales Contacto
A24: No-funcionales Contacto | B24: No-funcionales | C24: Ir a la hoja → | E24: Funcionales chatbotInformativo | H24: Tarjetas Bancolombia - Aprobado | I24: 4242 4242 4242 4242 | T24: Funcionales Seguimiento
A25: Funcionales Seguimiento | B25: Funcionales | C25: Ir a la hoja → | E25: Ir a la hoja → | H25: Tarjetas Bancolombia - Declinado | I25: 4111 1111 1111 1111 | T25: No-Funcionales Seguimiento
A26: No-Funcionales Seguimiento | B26: No-funcionales | C26: Ir a la hoja → | E26: Funcionales Checkout | T26: Funcionales Inversionistas
A27: Funcionales Inversionistas | B27: Funcionales | C27: Ir a la hoja → | E27: Ir a la hoja → | T27: No-funcionales Inversionistas
A28: No-funcionales Inversionistas | B28: No-funcionales | C28: Ir a la hoja → | E28: Funcionales Contacto | T28: Funcionales Devoluciones
A29: Funcionales Devoluciones | B29: Funcionales | C29: Ir a la hoja → | E29: Ir a la hoja → | T29: No-funcionales Devoluciones
A30: No-funcionales Devoluciones | B30: No-funcionales | C30: Ir a la hoja → | E30: Funcionales Cookies | T30: Funcionales Ayuda
A31: Funcionales Ayuda | B31: Funcionales | C31: Ir a la hoja → | E31: Ir a la hoja → | T31: No-funcionales Ayuda
A32: No-funcionales Ayuda | B32: No-funcionales | C32: Ir a la hoja → | E32: Funcionales Dashboard Admin | T32: Funcionales Prensa
A33: Funcionales Prensa | B33: Funcionales | C33: Ir a la hoja → | E33: Ir a la hoja → | T33: No-funcionales Prensa
A34: No-funcionales Prensa | B34: No-funcionales | C34: Ir a la hoja → | E34: Funcionales DB | T34: Funcionales Acerca de
A35: Funcionales Acerca de | B35: Funcionales | C35: Ir a la hoja → | E35: Ir a la hoja → | T35: No-funcionales Acerca de
A36: No-funcionales Acerca de | B36: No-funcionales | C36: Ir a la hoja → | E36: Funcionales Descuentos | T36: Funcionales chatbotInformativo
A37: Funcionales chatbotInformativo | B37: Funcionales | C37: Ir a la hoja → | E37: Ir a la hoja → | T37: No-funcionales chatbotInformati
... A56: Funcionales Categorías Admin | B56: Funcionales | C56: Ir a la hoja → | E56: Funcionales Perfil | T56: No-funcionales Categorias Admin
A57: No-funcionales Categorias Admin | B57: No-funcionales | C57: Ir a la hoja → | E57: Ir a la hoja → | S57: camilo | T57: Funcionales Usuario Admin
A58: Funcionales Usuario Admin | B58: Funcionales | C58: Ir a la hoja → | E58: Funcionales Politicas | T58: No-funcionales Usuarios Admin
...

Sheet Estadisticas
A1: Métrica | B1: Valor
A2: Cant. Requerimientos Funcionales | B2: ='Funcionales generales'!L3+'Funcionales DB'!L3+'Funcionales Homepage'!L3+'Funcionales Productos'!L3+'Funcionales Categoria'!L3+'Funcionales Descuentos'!L3+'Funcionales Cookies'!L3+'Funcionales Politicas'!L3+'Funcionales Terminos condicione'!L3+'Funcionales Perfil'!L3+'Funcionales Contacto'!L3+'Funcionales Seguimiento'!L3+'Funcionales Inversionistas'!L3+'Funcionales Devoluciones'!L3+'Funcionales Ayuda'!L3+'Funcionales Prensa'!L3+'Funcionales Acerca de'!L3+'Funcionales chatbotInformativo'!L3+'Funcionales LoginRegister'!L3+'Funcionales Producto'!L3+'Funcionales Carrito'!L3+'Funcionales Checkout'!L3+'Funcionales Favoritos'!L3+'Funcionales Dashboard Admin'!L3+'Funcionales Ordenes admin'!L3+'Funcionales Productos Admin'!L3+'Funcionales Categorías Admin'!L3+'Funcionales Usuario Admin'!L3+'Funcionales Atributos'!L3+'Funcionales Marcas'!L3+'Funcionales Proveedores Admin'!L3+'Funcionales Descuentos Admin'!L3+'Funcionales Puntos Admin'!L3+'Funcionales barra informativa '!L3+'No-funcionales barra informativ'!L3+'Funcionales Bot-Admin'!L3+'Funcionales Boton Ayuda'!L3 -> 490
A3: Cant. Requerimientos No-funcionales | B3: ='No-funcionales generales'!L3+'No-funcionales DB'!L3+'No-funcionales Homepage'!L3+'No-funcionales Productos'!L3+'No-funcionales Categoria'!L3+'No-funcionales Descuentos'!L3+'No-funcionales Cookies'!L3+'No-funcionales Politicas'!L3+'No-funcionales Terminos Condici'!L3+'No-funcionales Perfil'!L3+'No-funcionales Contacto'!L3+'No-Funcionales Seguimiento'!L3+'No-funcionales Inversionistas'!L3+'No-funcionales Devoluciones'!L3+'No-funcionales Ayuda'!L3+'No-funcionales Prensa'!L3+'No-funcionales Acerca de'!L3+'No-funcionales chatbotInformati'!L3+'No-funcionales LoginRegister'!L3+'No-funcionales Producto'!L3+'No-funcionales Carrito'!L3+'No-funcionales Checkout '!L3+'No-funcionales Favoritos'!L3+'No-funcionales Dashboard Admin'!L3+'No-funcionales Ordenes admin'!L3+'No-funcionales Productos Admin '!L3+'No-funcionales Categorias Admin'!L3+'No-funcionales Usuarios Admin'!L3+'No-funcionales Atributos'!L3+'No-funcionales Marcas '!L3+'No-funcionales Proveedores Admi'!L3+'No-funcionales Descuentos Admin'!L3+'No-funcionales Puntos Admin'!L3+'No-funcionales Bot-Admin'!L3+'No-funcionales Boton Ayuda'!L3 -> 815
A4: Total Requerimientos | B4: =B2+B3 -> 1305
A5: Cant. Funcionales Cumplidos | B5: ='Funcionales generales'!L4+'Funcionales DB'!L4+'Funcionales Homepage'!L4+'Funcionales Productos'!L4+'Funcionales Categoria'!L4+'Funcionales Descuentos'!L4+'Funcionales Cookies'!L4+'Funcionales Politicas'!L4+'Funcionales Terminos condicione'!L4+'Funcionales Perfil'!L4+'Funcionales Contacto'!L4+'Funcionales Seguimiento'!L4+'Funcionales Inversionistas'!L4+'Funcionales Devoluciones'!L4+'Funcionales Ayuda'!L4+'Funcionales Prensa'!L4+'Funcionales Acerca de'!L4+'Funcionales chatbotInformativo'!L4+'Funcionales LoginRegister'!L4+'Funcionales Producto'!L4+'Funcionales Carrito'!L4+'Funcionales Checkout'!L4+'Funcionales Favoritos'!L4+'Funcionales Dashboard Admin'!L4+'Funcionales Ordenes admin'!L4+'Funcionales Productos Admin'!L4+'Funcionales Categorías Admin'!L4+'Funcionales Usuario Admin'!L4+'Funcionales Atributos'!L4+'Funcionales Marcas'!L4+'Funcionales Proveedores Admin'!L4+'Funcionales Descuentos Admin'!L4+'Funcionales Puntos Admin'!L4+'Funcionales barra informativa '!L4+'No-funcionales barra informativ'!L4+'Funcionales Bot-Admin'!L4+'Funcionales Boton Ayuda'!L4 -> 485
A6: Cant. No-funcionales Cumplidos | B6: ='No-funcionales generales'!L4+'No-funcionales DB'!L4+'No-funcionales Homepage'!L4+'No-funcionales Productos'!L4+'No-funcionales Categoria'!L4+'No-funcionales Descuentos'!L4+'No-funcionales Cookies'!L4+'No-funcionales Politicas'!L4+'No-funcionales Terminos Condici'!L4+'No-funcionales Perfil'!L4+'No-funcionales Contacto'!L4+'No-Funcionales Seguimiento'!L4+'No-funcionales Inversionistas'!L4+'No-funcionales Devoluciones'!L4+'No-funcionales Ayuda'!L4+'No-funcionales Prensa'!L4+'No-funcionales Acerca de'!L4+'No-funcionales chatbotInformati'!L4+'No-funcionales LoginRegister'!L4+'No-funcionales Producto'!L4+'No-funcionales Carrito'!L4+'No-funcionales Checkout '!L4+'No-funcionales Favoritos'!L4+'No-funcionales Dashboard Admin'!L4+'No-funcionales Ordenes admin'!L4+'No-funcionales Productos Admin '!L4+'No-funcionales Categorias Admin'!L4+'No-funcionales Usuarios Admin'!L4+'No-funcionales Atributos'!L4+'No-funcionales Marcas '!L4+'No-funcionales Proveedores Admi'!L4+'No-funcionales Descuentos Admin'!L4+'No-funcionales Puntos Admin'!L4+'No-funcionales Bot-Admin'!L4+'No-funcionales Boton Ayuda'!L4 -> 815
A7: Total Cumplidos | B7: =B5+B6 -> 1300
A8: Porcentaje de Cumplimiento | B8: =IF(B4=0, 0, B7/B4) -> 0.99616858

Sheet Funcionales generales
B2: LISTADO DE REQUERIMIENTOS DE COMPRALO | K2: ESTADISTICAS
K3: Requirimientos | L3: =COUNT(B12:D86) -> 26
B4: SI | C4: Marque con una equis (X) si el sistema cumple con la función descrita | K4: Cumplidos | L4: =COUNTIF(F12:F86,"X") -> 26
B5: NO | C5: Marque con una equis (X) si el sistema no cumple con la función descrita
B6: ADI | C6: Marque con una equis (X) si el sistema debe adicionar la función descrita | K6: Porcentaje | L6: =PERCENTOF(L4,L3) -> #NAME?
B7: Observaciones: | D7: Espacio para complementar respuestas
F9: Nivel de cumplimiento | I9: OBSERVACIONES
B10: REQUISITOS FUNCIONALES GENERALES | F10: SI | G10: NO | H10: ADI
B12: 1 | C12: El sistema debe garantizar la seguridad de los datos almacenados mediante contraseñas, autenticación basada en JWT y control de acceso por roles (admin, usuario) | F12: x
B13: 2 | C13: El sistema debe permitir el manejo de datos personales por medio de cookies | F13: x
B14: 3 | C14: El sistema debe estar disponible 24/7 con un tiempo de actividad mínimo del 99% | F14: x
B15: 4 | C15: El sistema es multiusuario con roles diferenciados (administradores y clientes, clientes anonimos) | F15: x
B16: 5 | C16: El sistema debe ser compatible con navegadores modernos Chrome, Firefox, Safari, Edge | F16: x
B17: 6 | C17: El sistema debe permitir la encripción de contraseñas | F17: x
B18: 7 | C18: El sistema debe cumplir con normativas de protección de datos GDPR/LGPD | F18: x
B19: 8 | C19: El sistema debe soportar dispositivos móviles y tablets responsivamente | F19: x
B20: 9 | C20: El sistema debe permitir gestionar un catálogo de productos con jerarquía categoría → línea → sublínea, marcas, proveedores y variantes (color/talla/atributos). | F20: x
B21: 10 | C21: El sistema debe permitir gestionar inventario (entradas, salidas, ajustes y movimientos por producto/variante). | F21: x
B22: 11 | C22: El sistema debe incluir herramientas de accesibilidad | F22: x
B23: 12 | C23: El sistema debe permitir que el cliente final navegue el catálogo, filtre por múltiples criterios (categoría, precio, marca, proveedor, texto libre) y ordene los resultados. | F23: x
... B37: 26 | C37: El sistema debe permitir programar descuentos y campañas con fecha/hora de inicio y fin, aplicadas automáticamente. | F37: x

Sheet No-funcionales generales
B2: LISTADO DE REQUERIMIENTOS DE COMPRALO | K2: ESTADISTICAS
K3: Requirimientos | L3: =COUNT(B12:D92) -> 33
B4: SI | C4: Marque con una equis (X) si el sistema cumple con la función descrita | K4: Cumplidos | L4: =COUNTIF(F12:F92,"X") -> 33
B5: NO | C5: Marque con una equis (X) si el sistema no cumple con la función descrita
B6: ADI | C6: Marque con una equis (X) si el sistema debe adicionar la función descrita | K6: Porcentaje | L6: =PERCENTOF(L4,L3) -> #NAME?
B7: Observaciones: | D7: Espacio para complementar respuestas
F9: Nivel de cumplimiento | I9: OBSERVACIONES
B10: REQUISITOS NO FUNCIONALES GENERALES | F10: SI | G10: NO | H10: ADI
B12: 1 | C12: El sistema debe garantizar la seguridad de los datos almacenados mediante encriptación de contraseñas, autenticación basada en JWT y control de acceso por roles (admin, usuario) | F12: X
B13: 2 | C13: El sistema debe validar que todos los datos de entrada (productos, usuarios, proveedores,etc) estén completos mediante esquemas Pydantic y mostrar mensajes de error específicos para campos faltantes o inválidos | F13: X
B14: 3 | C14: El sistema debe ser capaz de escalar horizontalmente para adaptarse al crecimiento de usuarios y productos sin afectar el rendimiento mediante pooling de conexiones y cache | F14: x
B15: 4 | C15: La base de datos PostgreSQL debe permitir respaldos automáticos, gestión de transacciones ACID y optimización de consultas | F15: X
B16: 5 | C16: El sistema debe integrar con servicios externos de pagos (futuro) y notificaciones mediante APIs REST | F16: x
B17: 6 | C17: El sistema debe tener un tiempo máximo de respuesta de 2 segundos para operaciones CRUD de productos, usuarios y proveedores | F17: X
B18: 7 | C18: Los permisos de acceso al sistema podrán ser gestionados solo por usuarios con rol de administrador | F18: X
B19: 8 | C19: Ningún log debe contener contraseñas, tokens, números completos de tarjeta u otra información altamente sensible. | F19: X
B20: 9 | C20: El sistema debe utilizar PostgreSQL como motor de base de datos con funciones almacenadas para operaciones complejas | F20: X
B21: 10 | C21: El sistema debe contar con documentación API automática generada por FastAPI (Swagger/OpenAPI) y manuales de usuario | F21: X
B22: 11 | C22: El sistema debe procesar al menos 100 transacciones por segundo bajo carga normal | F22: X
B23: 12 | C23: El sistema debe manejar errores de forma centralizada con logging estructurado y códigos de estado HTTP apropiados | F23: X
... B44: 33 | C44: Soporte para caracteres Unicode (UTF-8) | F44: X

Sheet Funcionales DB
B2: LISTADO DE REQUERIMIENTOS DE COMPRALO | K2: ESTADISTICAS
K3: Requirimientos | L3: =COUNT(B12:D99) -> 24
B4: SI | C4: Marque con una equis (X) si el sistema cumple con la función descrita | K4: Cumplidos | L4: =COUNTIF(F12:F99,"X") -> 24
B5: NO | C5: Marque con una equis (X) si el sistema no cumple con la función descrita
B6: ADI | C6: Marque con una equis (X) si el sistema debe adicionar la función descrita | K6: Porcentaje | L6: =PERCENTOF(L4,L3) -> #NAME?
B7: Observaciones: | D7: Espacio para complementar respuestas
F9: Nivel de cumplimiento | I9: OBSERVACIONES
B10: REQUISITOS FUNCIONALES DB | F10: SI | G10: NO | H10: ADI
B12: 1 | C12: La tabla tab_products no debe almacenar precio ni stock; estos datos deben residir únicamente en tab_product_variant_combinations. | F12: X | I12: Requerimientos no funcionales
B13: 2 | C13: La base de datos debe permitir gestionar variantes mediante el modelo tab_product_variant_groups (agrupación lógica, p. ej. color) y tab_product_variant_combinations (combinación concreta de atributos). | F13: x | I13: Requerimientos no funcionales
B14: 3 | C14: Cada registro de tab_product_variant_combinations debe estar asociado a un grupo válido en tab_product_variant_groups mediante group_id. | F14: x | I14: Requerimientos no funcionales
B15: 4 | C15: Cada grupo de variantes (tab_product_variant_groups) puede tener múltiples imágenes (tab_product_variant_images) con orden y marca de principal (is_main). | F15: x | I15: Requerimientos no funcionales
B16: 5 | C16: La función fun_insert_producto debe crear productos en tab_products garantizando slug único y consistencia con categorías, marcas y proveedores. | F16: x | I16: Requerimientos no funcionales
B17: 6 | C17: La función fun_insert_product_variant debe insertar combinaciones en tab_product_variant_combinations generando un SKU único con fun_generate_sku y respetando | F17: x | I17: Requerimientos no funcionales
B18: 7 | C18: La función fun_insert_product_image debe registrar imágenes en tab_product_variant_images y asegurar que exista siempre una imagen principal por producto/grupo (o un valor por defecto). | F18: x | I18: Requerimientos no funcionales
B19: 8 | C19: Las funciones de filtro (fun_filter_products, fun_filter_admin_products, funciones de favoritos, etc.) deben obtener precios, stock total e imagen principal a partir de tab_product_variant_combinations + tab_product_variant_groups + tab_product_variant_images. | F19: x | I19: Requerimientos no funcionales
B20: 9 | C20: tab_carrito_productos y tab_orden_productos deben referenciar siempre una combinación válida mediante variant_id (tab_product_variant_combinations.id). | F20: x | I20: Requerimientos no funcionales
B21: 10 | C21: Las columnas opciones_elegidas en tab_carrito_productos y tab_orden_productos deben almacenar en JSONB los atributos elegidos (color, talla, etc.) coherentes con tab_product_variant_combinations.attributes. | F21: x | I21: Requerimientos no funcionales
B22: 11 | C22: La función fun_obtener_carrito_usuario debe crear o recuperar un carrito único por usuario o session_id, garantizando que no existan carritos duplicados activos por la misma clave. | F22: x | I22: Requerimientos no funcionales
B23: 12 | C23: La función fun_agregar_producto_carrito debe validar existencia y estado (is_active) de la combinación, verificar stock disponible y actualizar/incrementar la línea en tab_carrito_productos con sus opciones_elegidas. | F23: x | I23: Requerimientos no funcionales
... B35: 24 | C35: Toda actualización de tab_ordenes.ind_estado a un estado final (completada, cancelada, etc.) debe ir acompañada de movimientos consistentes en tab_movimientos_inventario y tab_movimientos_puntos según la lógica de negocio. | F35: x | I35: Requerimientos no funcionales

Sheet No-funcionales DB
B2: LISTADO DE REQUERIMIENTOS DE COMPRALO | K2: ESTADISTICAS
K3: Requirimientos | L3: =COUNT(B12:D33) -> 20
B4: SI | C4: Marque con una equis (X) si el sistema cumple con la función descrita | K4: Cumplidos | L4: =COUNTIF(F12:F33,"X") -> 20
B5: NO | C5: Marque con una equis (X) si el sistema no cumple con la función descrita
B6: ADI | C6: Marque con una equis (X) si el sistema debe adicionar la función descrita | K6: Porcentaje | L6: =PERCENTOF(L4,L3) -> #NAME?
B7: Observaciones: | D7: Espacio para complementar respuestas
F9: Nivel de cumplimiento | I9: OBSERVACIONES
B10: REQUISITOS NO FUNCIONALES DB | F10: SI | G10: NO | H10: ADI
B12: 1 | C12: La base de datos debe mantener integridad referencial entre todas las tablas mediante claves foráneas, incluyendo la nueva relación producto → grupo → combinación → carrito/orden. | F12: x
B13: 2 | C13: Las transacciones que involucren carrito, órdenes, pagos, inventario, descuentos y puntos deben ser ACID: o se confirman todos los cambios o se revierte todo. | F13: x
B14: 3 | C14: Los cambios de estado de una orden deben ser atómicos respecto a las actualizaciones de stock y puntos. | F14: x
B15: 4 | C15: Las consultas de catálogo que usan fun_filter_products y fun_filter_admin_products sobre tab_products + tab_product_variant_groups + tab_product_variant_combinations deben devolver resultados paginados en tiempos aceptables (por ejemplo, < 300 ms para catálogos de hasta ~10.000 productos). | F15: x
B16: 5 | C16: Las consultas que calculan precios mínimos/máximos y stock total por producto a partir de tab_product_variant_combinations deben aprovechar índices y evitar escaneos completos innecesarios. | F16: x
B17: 6 | C17: La recuperación del carrito (fun_obtener_carrito_detalle) y el cálculo de totales (fun_calcular_total_carrito) deben ejecutarse típicamente en menos de ~200 ms para carritos de tamaño razonable. | F17: x
B18: 7 | C18: La creación de una orden desde carrito (fun_crear_orden_desde_carrito) debe completarse en un tiempo acotado (p.ej. < 1 segundo en condiciones normales), incluyendo inserciones en órdenes, líneas y movimientos de inventario. | F18: x
B19: 8 | C19: Las consultas de historial de órdenes (fun_obtener_ordenes_usuario) y de puntos (fun_obtener_resumen_puntos_usuario) deben soportar miles de registros por usuario manteniendo tiempos de respuesta aceptables (p.ej. < 500 ms). | F19: x
B20: 9 | C20: Los reportes de ventas por producto/categoría (tab_estadisticas_productos, tab_estadisticas_categorias y vistas/funciones asociadas) deben apoyarse en índices o tablas resumen para no degradar el rendimiento de las tablas transaccionales. | F20: x
B21: 10 | C21: Deben existir índices sobre columnas de filtrado frecuente: tab_product_variant_groups.product_id, tab_product_variant_combinations.group_id, tab_product_variant_combinations.is_active, slugs de categorías/productos y campos de búsqueda por texto. | F21: x
B22: 11 | C22: El índice GIN sobre tab_product_variant_combinations.attributes debe ser utilizado por las consultas que filtren por atributos dinámicos, equilibrando coste de escritura y rendimiento de lectura. | F22: x
B23: 12 | C23: Las tablas de alta escritura (tab_carrito_productos, tab_orden_productos, tab_movimientos_inventario, tab_movimientos_puntos) deben tener índices alineados con sus consultas principales sin penalizar de forma excesiva las inserciones. | F23: x
... B31: 20 | C31: Los logs de auditoría no deben almacenar información excesivamente sensible; cuando sea necesario, se deben anonimizar o truncar valores. | F31: x

Sheet Funcionales Homepage
B2: LISTADO DE REQUERIMIENTOS DE COMPRALO | K2: ESTADISTICAS
K3: Requirimientos | L3: =COUNT(B12:D99) -> 83
B4: SI | C4: Marque con una equis (X) si el sistema cumple con la función descrita | K4: Cumplidos | L4: =COUNTIF(F12:F99,"X") -> 81
B5: NO | C5: Marque con una equis (X) si el sistema no cumple con la función descrita
B6: ADI | C6: Marque con una equis (X) si el sistema debe adicionar la función descrita | K6: Porcentaje | L6: =PERCENTOF(L4,L3) -> #NAME?
B7: Observaciones: | D7: Espacio para complementar respuestas
B8: https://compralo.revital.cloud/
F9: Nivel de cumplimiento | I9: Observaciones
B10: REQUERIMIENTOS FUNCIONALES DEL HOME | F10: SI | G10: NO | H10: ADI
B12: 1 | C12: La home debe mostrar una barra superior informativa con mensajes clave (por ejemplo “Envíos gratis desde $X”) configurable por administrador, es posible cerrar la barra informativa con un boton de la parte derecha. | F12: X | I12: Cumple, NOTA: No se menciona la opcion de cerrar el mensaje en los requerimiento
B13: 2 | C13: La home debe mostrar un **header fijo** con: logo de la tienda, menú principal (`Inicio`, `Productos`, `Descuentos`, `Contacto`), buscador, icono de carrito, acceso a cuenta y selector de tema/color (si está habilitado). | F13: X | I13: Cumple
B14: 3 | C14: El **logo** en el header debe redirigir siempre a la home al hacer clic. | F14: X | I14: Cumple
B15: 4 | C15: El **menú principal de navegación** debe verse destacado en rojo según la sección actual (por ejemplo, `Inicio` resaltado en la homepage). Feature solo para desktop | F15: X | I15: Cumple
B16: 5 | C16: La **barra de búsqueda** de la home debe permitir buscar productos por texto y redirigir a la vista de catálogo (`/products`) mostrando los resultados filtrados. | F16: X | I16: Cumple
B17: 6 | C17: La home debe mostrar una **sección hero** con imagen/ilustración principal, título, subtítulo y al menos dos botones de llamada a la acción (“Ver productos” y “Ver categorías”). | F17: X | I17: Cumple, NOTA: No se especifica todo el contenido de la seccion hero como las metricas debajo del logo, el color de los botones, etc.
B18: 7 | C18: Al hacer clic en “Ver productos” desde el hero, el usuario debe ser redirigido a la página de catálogo de productos. | F18: X | I18: Cumple
B19: 8 | C19: Al hacer clic en “Ver categorías” desde el hero, el usuario debe ser redirigido a la página de categorías | F19: X | I19: Cumple
B20: 9 | C20: La home debe mostrar una **sección de categorías destacadas** con tarjetas para las categorías principales (por ejemplo: Electrónica, Moda, Hogar, Videojuegos, Mascotas, Ferretería). | F20: X | I20: Cumple, NOTA: No se menciona el numero de tarjetas por cada linea ni el color. Existe un boton "Ver Todas las Categorias" que no se menciona en los requerimientos
B21: 10 | C21: Cada tarjeta de categoría debe incluir nombre, breve descripción/etiqueta y fondo/ícono representativo. | F21: X | I21: Cumple
B22: 11 | C22: Al hacer clic en una categoría de la home, el usuario debe ser redirigido a una vista filtrada de catálogo que muestre las lineas de esa categoría. | F22: X | I22: Cumple,
B23: 12 | C23: La home debe mostrar una **sección de productos destacados** con un carrusel o grilla de tarjetas de producto (imagen, nombre, precio, rating/resumen y botón "ver detalles"). | F23: X | I23: Cumple, NOTA: Existe un boton "Ver Todos los Productos" que no se menciona en los requerimientos
... B25: 14 | C25: Al hacer clic en “Ver Detalles” en un producto destacado, el usuario debe ser redirigido a la página de detalle del producto correspondiente. | F25: X | I25: Cumple
B26: 15 | C26: Si un producto destacado tiene descuento, la tarjeta debe mostrar de forma clara el precio anterior, el porcentaje o monto de descuento y el precio final. | F26: x
B27: 16 | C27: La home debe mostrar una **sección de testimonios de clientes** con tarjetas que incluyan nombre, rol/segmento del cliente, foto/avatar y texto del testimonio. | F27: X | I27: Cumple, NOTA: Existe un boton "Empezar a comprar" que no se menciona en los requerimientos
B28: 17 | C28: Solo se mostraran las 3 ultimas reseñas. | F28: x
B29: 18 | C29: La home debe mostrar una **banda de beneficios** (por ejemplo: Envío Gratis, Compra Segura, Devoluciones, Pago Seguro) con iconos y texto corto. | F29: X | I29: No Cumple, la banda de beneficios se encuentra en el footer
B30: 19 | C30: El **footer** de la home debe incluir información corta "Acerca de nosotros" | F30: X | I30: Cumple
B31: 20 | C31: El **footer** de la home debe incluir listas de enlaces a categorías, líneas y sublíneas | F31: X | I31: Cumple
B32: 21 | C32: El **footer** de la home debe incluir enlaces de empresa (Acerca de, Contacto, Blog, Prensa, Inversionistas), | F32: X | I32: Cumple
B33: 22 | C33: El **footer** de la home debe incluir enlaces a secciones de ayuda del cliente (Mi cuenta, Seguir pedido, Centro de ayuda, Devoluciones), | F33: X | I33: Cumple
B34: 23 | C34: El **footer** de la home debe incluir enlaces legales (Términos y condiciones, Política de privacidad, Política de cookies, Accesibilidad, Configurar cookies) | F34: X | I34: Cumple
B35: 24 | C35: El **footer** de la home debe incluir Iconos de redes sociales que redireccione a las homepage de cada red social | F35: X | I35: Cumple
B36: 25 | C36: El **footer** de la home debe incluir logos de metodo de pago soportados | F36: X | I36: Cumple, NOTA: No hay requerimiento sobre el mensaje de copyright al final del footer
B37: 26 | C37: Todos los enlaces del footer deben redirigir a las páginas correspondientes dentro del sitio o a URLs externas configuradas. | F37: X | I37: No cumple, el link "Mi Cuenta" redirige al home
B38: 27 | C38: En la esquina inferior derecha de la home debe aparecer un **botón flotante de carrito** que abra el widget del chatbot | F38: X | I38: Cumple
B39: 28 | C39: La home debe mostrar el **widget de chatbot informativo** que al abrirse ofrezca un menú de opciones (términos, datos, descuentos, puntos, garantías) y responda usando datos de descuentos y puntos activos. | F39: X | I39: Cumple
B40: 29 | C40: la homepage debe mostrar el **banner de cookies** en la primera visita hasta que el usuario tome una decisión (aceptar todas, solo necesarias o configurar). | F40: X | I40: Cumple
... B43: 32 | C43: La home debe mostrar indicadores de sesión en el header: si el usuario está autenticado, mostrar acceso a su cuenta/perfil; si no, mostrar enlaces “Iniciar sesión” y “Registrarse” o equivalente. | F43: X | I43: Cumple
B44: 33 | C44: La home debe poder ocultar/mostrar secciones (por ejemplo testimonios, productos destacados, CTA secundaria) mediante parámetros de configuración por instancia sin requerir cambios de código. | H44: x
B45: 34 | C45: La home debe permitir que el administrador configure los textos principales (hero, beneficios, mensajes de barra superior, títulos de secciones) de acuerdo con el branding de cada instancia. | E45: Información corta “Acerca de nosotros”, | H45: x
...

Sheet No-funcionales Homepage
B2: LISTADO DE REQUERIMIENTOS DE COMPRALO | K2: ESTADISTICAS
K3: Requirimientos | L3: =COUNT(B12:D100) -> 35
B4: SI | C4: Marque con una equis (X) si el sistema cumple con la función descrita | K4: Cumplidos | L4: =COUNTIF(F12:F100,"X") -> 35
B5: NO | C5: Marque con una equis (X) si el sistema no cumple con la función descrita | K5: Porcentaje | L5: =PERCENTOF(L4,L3) -> #NAME?
B6: ADI | C6: Marque con una equis (X) si el sistema debe adicionar la función descrita
B7: Observaciones: | D7: Espacio para complementar respuestas
B8: https://compralo.revital.cloud/
F9: Nivel de cumplimiento | I9: Observaciones
B10: REQUERIMIENTOS NO FUNCIONALES DEL HOME | F10: SI | G10: NO | H10: ADI
B12: 1 | C12: El slider debe ser responsive en móviles | F12: X
B13: 2 | C13: Las imágenes deben optimizarse automáticamente | F13: X
B14: 3 | C14: La página debe ser accesible con navegación por teclado | F14: X
B15: 4 | C15: La home debe aplicar técnicas de **lazy loading** para imágenes y secciones que no son visibles inicialmente, reduciendo el tiempo de carga inicial. | F15: X
B16: 5 | C16: El slider/banner debe ser responsive y adaptarse a móviles, tablets y desktop | F16: X
B17: 6 | C17: Las imágenes de productos deben optimizarse automáticamente (WebP, compresión) | F17: X
B18: 7 | C18: La interfaz debe mantener contraste mínimo 4.5:1 para accesibilidad WCAG 2.1 | F18: X
B19: 8 | C19: La galería de imágenes debe soportar zoom fluido sin lag perceptible | F19: X
B20: 9 | C20: El formulario de checkout debe validarse en tiempo real con feedback visual | F20: X
B21: 10 | C21: La página debe ser compatible con Chrome, Firefox, Safari, Edge (últimas 2 versiones) | F21: X
B22: 11 | C22: El cambio entre modo claro/oscuro debe ser instantáneo sin parpadeos | F22: X
B23: 12 | C23: Los botones deben tener estados hover, active y disabled claramente diferenciados | F23: X
... B46: 35 | C46: La home debe respetar las preferencias de cookies del usuario: si ha rechazado cookies no esenciales, no se deben disparar scripts analíticos/marketing desde la home hasta que cambie su configuración. | F46: X

Sheet Funcionales Productos
B2: LISTADO DE REQUERIMIENTOS DE COMPRALO | K2: ESTADISTICAS
K3: Requirimientos | L3: =COUNT(B12:D75) -> 9
B4: SI | C4: Marque con una equis (X) si el sistema cumple con la función descrita | K4: Cumplidos | L4: =COUNTIF(F12:F75,"X") -> 8
B5: NO | C5: Marque con una equis (X) si el sistema no cumple con la función descrita | K5: Porcentaje | L5: =PERCENTOF(L4,L3) -> #NAME?
B6: ADI | C6: Marque con una equis (X) si el sistema debe adicionar la función descrita
B7: Observaciones: | D7: Espacio para complementar respuestas
B8: https://compralo.revital.cloud/products
F10: Nivel de cumplimiento | I10: Observaciones
B11: REQUERIMIENTOS FUNCIONALES PRODUCTOS | F11: SI | G11: NO | H11: ADI
B13: 1 | C13: La página de productos debe mostrar un listado paginado de productos basado en los filtros y criterios de ordenamiento seleccionados por el usuario. | F13: x | I13: Cumple
B14: 2 | C14: Cada tarjeta de producto debe mostrar al menos imagen principal, nombre, rango de precios cuando existan variantes. | F14: x | I14: Cumple
B15: 3 | C15: La página debe permitir filtrar productos por rango de precio mínimo y máximo mediante controles específicos en el panel de filtros. | F15: x
B16: 4 | C16: La página debe permitir filtrar productos por categoría, línea y sublínea utilizando una navegación jerárquica en el panel de filtros. | F16: x
B17: 5 | C17: La página debe permitir filtrar productos por marca y, pudiendo seleccionar una o varias opciones simultáneamente. | F17: x
B18: 6 | C18: La página debe ofrecer filtros de disponibilidad (por ejemplo “Solo en stock”, “Solo con descuento”) que limiten el listado a productos que cumplan dichas condiciones. | H18: x
B19: 7 | C19: La página debe mostrar una sección de filtros activos (chips o etiquetas) que resuma todos los filtros aplicados y permita quitarlos individualmente o limpiar todos a la vez. | F19: x
B20: 8 | C20: La página debe ofrecer un selector de ordenamiento con al menos las opciones por nombre, por precio (ascendente y descendente) y por relevancia o más vendidos. | F20: x
B21: 9 | C21: La página debe permitir cambiar entre al menos dos modos de visualización del listado (por ejemplo, vista de cuadrícula y vista de lista), recordando la preferencia del usuario cuando sea posible. | F21: x

Sheet No-funcionales Productos
B2: LISTADO DE REQUERIMIENTOS DE COMPRALO | K2: ESTADISTICAS
K3: Requirimientos | L3: =COUNT(B12:D100) -> 30
B4: SI | C4: Marque con una equis (X) si el sistema cumple con la función descrita | K4: Cumplidos | L4: =COUNTIF(F12:F100,"X") -> 30
B5: NO | C5: Marque con una equis (X) si el sistema no cumple con la función descrita | K5: Porcentaje | L5: =PERCENTOF(L4,L3) -> #NAME?
B6: ADI | C6: Marque con una equis (X) si el sistema debe adicionar la función descrita
B7: Observaciones: | D7: Espacio para complementar respuestas
F10: Nivel de cumplimiento | I10: Observaciones
B11: REQUERIMIENTOS NO FUNCIONALES PRODUCTOS | F11: SI | G11: NO | H11: ADI
B13: 1 | C13: El contenido inicial de la página (primer bloque de productos visible y filtros básicos) debe cargarse en menos de ~3 segundos en conexiones de banda ancha típicas. | F13: x
B14: 2 | C14: Las consultas al backend que alimentan el listado de productos deben estar paginadas y usar índices adecuados sobre categoría, precio, estado y marca para evitar escaneos completos de tablas. | F14: x
B15: 3 | C15: La API que lista productos debe mantener un tiempo de respuesta objetivo P95 menor a 500 ms bajo carga normal, incluyendo la aplicación de filtros estándar. | F15: x
B16: 4 | C16: Las imágenes de productos deben cargarse utilizando técnicas de lazy loading para elementos fuera del viewport, reduciendo el peso inicial de la página. | F16: x
B17: 5 | C17: Los formatos y tamaños de imagen utilizados en la página de productos deben estar optimizados (compresión, tamaños adaptativos) para equilibrar calidad visual y rendimiento. | F17: x
B18: 6 | C18: La reserva de espacio para imágenes y tarjetas debe evitar saltos de layout significativos (CLS), manteniendo la estructura estable durante la carga. | F18: x
B19: 7 | C19: El control de rango de precio (inputs o slider) debe responder sin bloqueos perceptibles al usuario, aplicando el filtro mediante solicitudes asincrónicas o recarga controlada. | F19: x
B20: 8 | C20: La aplicación de filtros de precio no debe degradar de forma notable el tiempo de respuesta de la página, manteniendo un comportamiento similar al de otros filtros. | F20: x
B21: 9 | C21: El formato de precios mostrado en la página debe ser consistente con la configuración regional de la instancia (separadores de miles, símbolo de moneda, número de decimales). | F21: x
B22: 10 | C22: La navegación jerárquica de categorías, líneas y sublíneas debe ser completamente responsiva, adaptándose a una columna expandible en móvil y a un panel lateral en escritorio sin solapamientos. | F22: x
B23: 11 | C23: Las consultas para filtrar por categoría, línea y sublínea deben aprovechar índices compuestos o vistas preparadas para que el rendimiento se mantenga estable incluso con catálogos grandes. | F23: x
B24: 12 | C24: Los textos de nombres y descripciones de categorías, líneas y sublíneas deben truncarse de forma elegante en el panel de filtros para evitar desbordes en pantallas pequeñas. | F24: x
... B42: 30 | C42: En el flujo de añadir al carrito, los errores (por ejemplo, falta de stock o selección de variante incompleta) deben manejarse con mensajes claros y no bloquear el resto de interacciones en la página | F42: x

Sheet Funcionales Categoria
B2: LISTADO DE REQUERIMIENTOS DE COMPRALO | K2: ESTADISTICAS
K3: Requirimientos | L3: =COUNT(B12:D96) -> 10
B4: SI | C4: Marque con una equis (X) si el sistema cumple con la función descrita | K4: Cumplidos | L4: =COUNTIF(F12:F96,"X") -> 10
B5: NO | C5: Marque con una equis (X) si el sistema no cumple con la función descrita | K5: Porcentaje | L5: =PERCENTOF(L4,L3) -> #NAME?
B6: ADI | C6: Marque con una equis (X) si el sistema debe adicionar la función descrita
B7: Observaciones: | D7: Espacio para complementar respuestas
F10: Nivel de cumplimiento | I10: Observaciones
B11: REQUERIMIENTOS FUNCIONALES CATEGORIA | F11: SI | G11: NO | H11: ADI
B13: 1 | C13: La sección de categorías debe mostrar una cuadrícula de tarjetas de todas las categorías activas del catálogo, cada una con nombre, breve descripción y un ícono o imagen representativa. | F13: X | I13: cumple Pregunta: ¿Las categorías activas sin productos deben mostrarse en el catálogo o deben ocultarse?
B14: 2 | C14: Cada tarjeta de categoría debe mostrar el número de productos asociados a esa categoría (por ejemplo “4 productos”) calculado a partir del catálogo actual. | F14: X | I14: cumple
B15: 3 | C15: Al hacer clic en una tarjeta de categoría, el sistema debe navegar a una vista de detalle de categoría donde se muestren las líneas asociadas (por ejemplo /categories/[id_category]) | F15: X | I15: cumple Nota: Esto debe ir en requerimientos No Funcionales (por ejemplo /categories/[id_category])
B16: 4 | C16: La vista de detalle de categoría debe listar todas las líneas pertenecientes a esa categoría como tarjetas, cada una con nombre, descripción corta y contador de productos asociados. | F16: X | I16: cumple Nota: la descripción debe ser un poco más específica acerca de las características del producto
B17: 5 | C17: Al hacer clic en una tarjeta de línea, el sistema debe navegar a una vista de detalle de línea donde se muestren las sublíneas correspondientes (por ejemplo /categories/[id_line]) | F17: X | I17: cumple
B18: 6 | C18: La vista de detalle de línea debe listar todas las sublíneas como tarjetas con nombre y contador de productos, y permitir navegar a la vista de productos filtrados por esa sublínea. | F18: X | I18: cumple
B19: 7 | C19: En cualquier nivel (categoría, línea, sublínea) la sección debe ofrecer un enlace o botón claro para volver al nivel inmediatamente anterior. | F19: X | I19: cumple Nota: Cuando se le da clic al producto para ver las específicaciones no se puede volver atrás.
B20: 8 | C20: La vista de nivel más profundo (por ejemplo, sublínea) debe mostrar, además de la tarjeta de sublínea, un listado de productos filtrados exclusivamente por esa sublínea. | F20: X | I20: cumple
B21: 9 | C21: Cuando el número de categorías sea mayor que la capacidad de la cuadrícula, la sección debe ofrecer paginación para navegar entre páginas de categorías. | F21: X | I21: cumple
B22: 10 | C22: La sección de categorías, en todos sus niveles, debe reutilizar el mismo header, barra superior y footer que el resto del sitio, manteniendo activo el ítem de menú “Productos” según la navegación definida. | F22: X | I22: cumple

Sheet No-funcionales Categoria
B2: LISTADO DE REQUERIMIENTOS DE COMPRALO | K2: ESTADISTICAS
K3: Requirimientos | L3: =COUNT(B12:D100) -> 40
B4: SI | C4: Marque con una equis (X) si el sistema cumple con la función descrita | K4: Cumplidos | L4: =COUNTIF(F12:F100,"X") -> 40
B5: NO | C5: Marque con una equis (X) si el sistema no cumple con la función descrita | K5: Porcentaje | L5: =PERCENTOF(L4,L3) -> #NAME?
B6: ADI | C6: Marque con una equis (X) si el sistema debe adicionar la función descrita
B7: Observaciones: | D7: Espacio para complementar respuestas
F10: Nivel de cumplimiento | I10: Observaciones
B11: REQUERIMIENTOS NO FUNCIONALES CATEGORIA | F11: SI | G11: NO | H11: ADI
B13: 1 | C13: El tiempo de carga inicial de la cuadrícula de categorías (primer “fold”) no debe exceder ~3 segundos en conexiones de banda ancha típicas. | F13: x
B14: 2 | C14: Las consultas a la base de datos para obtener el listado de categorías deben estar paginadas y usan índices sobre las columnas de estado y orden de visualización para evitar escaneos completos innecesarios. | F14: x
B15: 3 | C15: El cálculo de contadores de productos por categoría debe realizarse mediante vistas/materializaciones o consultas agregadas optimizadas para no degradar el rendimiento al crecer el catálogo. | F15: x
B16: 4 | C16: El layout de la cuadrícula de categorías debe ser completamente responsivo, mostrando 1–2 columnas en móvil, 2–3 en tablet y ≥4 en escritorio sin solapamiento de contenido. | F16: x
B17: 5 | C17: Las tarjetas de categoría deben mantener un tamaño mínimo táctil de acuerdo con las recomendaciones de accesibilidad (al menos 44x44 px en dispositivos táctiles). | F17: x
B18: 6 | C18: Los textos de nombre y descripción de cada categoría deben truncarse de forma elegante (con ellipsis) para evitar desbordes o saltos de layout inesperados. | F18: x
B19: 7 | C19: Las imágenes o íconos de las tarjetas de categoría deben cargarse con técnicas de lazy loading para minimizar el peso inicial de la página. | F19: x
B20: 8 | C20: Los colores y contrastes usados en títulos y tarjetas de categorías deben cumplir como mínimo el nivel AA de WCAG 2.1 para asegurar legibilidad en todos los dispositivos. | F20: x
B21: 9 | C21: La cuadrícula y los controles de paginación deben ser completamente navegables por teclado, con un orden de tabulación lógico y focos visibles en todos los elementos interactivos. | F21: x
B22: 10 | C22: Las consultas que devuelven líneas asociadas a una categoría deben filtrar solo líneas activas y aprovechar índices sobre category_id y is_active para reducir la latencia. | F22: x
B23: 11 | C23: La vista de detalle de categoría debe renderizar las tarjetas de líneas sin provocar reflujo visual significativo; se deben reservar alturas aproximadas para las tarjetas antes de cargar su contenido. | F23: x
B24: 12 | C24: Los textos de encabezados y descripciones en la vista de detalle de categoría deben ser internacionalizables, permitiendo cambiar de idioma sin modificar el código de la página. | F24: x
... B52: 30 | C52: Cualquier animación usada en las tarjetas de categorías (hover, focus, transiciones) debe ejecutarse de forma fluida (60 fps objetivo) y no debe bloquear la interacción ni provocar mareo o distracción excesiva. | F52: x

Sheet Funcionales Descuentos
B2: LISTADO DE REQUERIMIENTOS DE COMPRALO | K2: ESTADISTICAS
K3: Requirimientos | L3: =COUNT(B12:D99) -> 9
B4: SI | C4: Marque con una equis (X) si el sistema cumple con la función descrita | K4: Cumplidos | L4: =COUNTIF(F12:F99,"X") -> 9
B5: NO | C5: Marque con una equis (X) si el sistema no cumple con la función descrita | K5: Porcentaje | L5: =PERCENTOF(L4,L3) -> #NAME?
B6: ADI | C6: Marque con una equis (X) si el sistema debe adicionar la función descrita
B7: Observaciones: | D7: Espacio para complementar respuestas
B8: https://compralo.revital.cloud/discounts
F10: Nivel de cumplimiento | I10: Observaciones
B11: REQUERIMIENTOS FUNCIONALES DESCUENTOS | F11: SI | G11: NO | H11: ADI
B13: 1 | C13: La sección de descuentos debe mostrar un listado de todos los descuentos activos, cada uno en una tarjeta con nombre, porcentaje o monto de descuento y descripción corta. | F13: x | I13: Cumple
B14: 2 | C14: Cada tarjeta de descuento debe mostrar claramente el tipo de descuento (porcentaje o monto fijo) y el valor correspondiente (por ejemplo “50.00%” o “$50.000”). | F14: x | I14: Cumple
B15: 3 | C15: Cada descuento debe indicar a qué ámbito aplica: categoría específica, subconjunto de productos, carrito completo u otros criterios definidos en la configuración. | F15: x | I15: Cumple
B16: 4 | C16: La tarjeta de descuento debe mostrar el período de vigencia (fecha de inicio y fecha de fin) y, si corresponde, un indicador de estado (por ejemplo “Próximo”, “Activo”, “Pronto a expirar”). | F16: x | I16: Cumple. NOTA: No se pudo verificar el indicador de estado
B17: 5 | C17: La sección de descuentos debe permitir mostrar ejemplos concretos de precios antes y después de aplicar el descuento (por ejemplo “$100.000 → $50.000”) para ilustrar el beneficio. | F17: x | I17: Cumple
B18: 6 | C18: La sección de descuentos debe indicar, cuando aplique, si el descuento requiere condiciones especiales, como un cupón, un mínimo de compra o pertenecer a un segmento de clientes. | F18: x | I18: Cumple
B19: 7 | C19: La sección de descuentos debe mostrar solo los descuentos que estén realmente disponibles para el usuario actual, excluyendo aquellos reservados a otros segmentos o ya expirados. | F19: x
B20: 8 | C20: La sección de descuentos debe manejar el caso “sin descuentos disponibles” mostrando un estado vacío con mensaje amigable y sugerencias (por ejemplo ver productos o suscribirse a un boletín). | F20: x | I20: Cumple
B21: 9 | C21: La sección de descuentos debe convivir con la estructura global de la app (header, barra superior, footer, chatbot, botón flotante de carrito) sin interferir en su funcionamiento ni en la navegación principal. | F21: x | I21: cumple NOTA: el requerimiento es funcional, pero la forma en que está redactado usa términos técnicos (“estructura global”, “chatbot”, “botón flotante de carrito”)

Sheet No-funcionales Descuentos
B2: LISTADO DE REQUERIMIENTOS DE COMPRALO | K2: ESTADISTICAS
K3: Requirimientos | L3: =COUNT(B12:D100) -> 30
B4: SI | C4: Marque con una equis (X) si el sistema cumple con la función descrita | K4: Cumplidos | L4: =COUNTIF(F12:F100,"X") -> 30
B5: NO | C5: Marque con una equis (X) si el sistema no cumple con la función descrita | K5: Porcentaje | L5: =PERCENTOF(L4,L3) -> #NAME?
B6: ADI | C6: Marque con una equis (X) si el sistema debe adicionar la función descrita
B7: Observaciones: | D7: Espacio para complementar respuestas
B8: https://compralo.revital.cloud/discounts
F10: Nivel de cumplimiento | I10: Observaciones
B11: REQUERIMIENTOS NO FUNCIONALES DESCUENTOS | F11: SI | G11: NO | H11: ADI
B13: 1 | C13: El listado inicial de descuentos debe cargarse en menos de aproximadamente 2 segundos en conexiones de banda ancha típicas. | F13: x
B14: 2 | C14: La consulta que obtiene los descuentos activos debe filtrar por fecha de vigencia y estado para evitar recorrer descuentos expirados o desactivados. | F14: x
B15: 3 | C15: El endpoint que lista descuentos debe mantener un tiempo de respuesta objetivo P95 menor a 500 ms bajo carga normal. | F15: x
B16: 4 | C16: El formato de porcentajes y montos debe seguir la configuración regional de la instancia (símbolo de moneda, separadores de miles y decimales). | F16: x
B17: 5 | C17: Los valores de descuento deben formatearse de forma consistente en toda la interfaz para reducir ambigüedades y errores de interpretación. | F17: x
B18: 6 | C18: La lógica que calcula y muestra los valores de descuento debe estar cubierta por pruebas automatizadas que validen diversos casos (porcentajes altos, montos pequeños, redondeos). | F18: x
B19: 7 | C19: La obtención de la información de ámbito (categorías, productos, reglas) debe realizarse con consultas optimizadas (joins mínimos, uso de índices sobre columnas de relación). | F19: x
B20: 8 | C20: La descripción del ámbito de aplicación debe generarse a partir de datos estructurados y ser fácilmente traducible a otros idiomas sin cambios de código. | F20: x
B21: 9 | C21: Los textos que explican el ámbito deben ser claros, concisos y evitar tecnicismos innecesarios para disminuir el riesgo de reclamaciones por malentendidos. | F21: x
B22: 10 | C22: El cálculo de estados de vigencia (próximo, activo, pronto a expirar, expirado) debe basarse en la zona horaria configurada para la instancia y no en la hora local del navegador. | F22: x
B23: 11 | C23: El formato de fechas mostrado para vigencia debe ser consistente en toda la aplicación y configurable por región (por ejemplo, DD/MM/AAAA o MM/DD/YYYY). | F23: x
B24: 12 | C24: El refresco del estado visual de vigencia no debe requerir recargar toda la página; idealmente debe recalcularse en cliente o con llamadas ligeras al backend. | F24: x
... B42: 30 | C42: La sección de descuentos debe respetar las preferencias de cookies y privacidad del usuario, evitando la ejecución de scripts analíticos o de marketing si no se ha otorgado el consentimiento correspondiente. | F42: x

Sheet Funcionales Cookies
A1: mino
B2: LISTADO DE REQUERIMIENTOS DE COMPRALO | K2: ESTADISTICAS
K3: Requirimientos | L3: =COUNT(B12:D73) -> 8
B4: SI | C4: Marque con una equis (X) si el sistema cumple con la función descrita | K4: Cumplidos | L4: =COUNTIF(F12:F73,"X") -> 8
B5: NO | C5: Marque con una equis (X) si el sistema no cumple con la función descrita | K5: Porcentaje | L5: =PERCENTOF(L4,L3) -> #NAME?
B6: ADI | C6: Marque con una equis (X) si el sistema debe adicionar la función descrita
B7: Observaciones: | D7: Espacio para complementar respuestas
F10: Nivel de cumplimiento | I10: Observaciones
B11: REQUERIMIENTOS FUNCIONALES COOKIES | F11: SI | G11: NO | H11: ADI
B13: 1 | C13: La sección de Política de Cookies debe explicar de forma clara qué son las cookies y para qué se utilizan en la tienda Compralo. | F13: x | I13: Cumple
B14: 2 | C14: La sección debe describir los distintos tipos de cookies que utiliza el sitio (necesarias, funcionales, analíticas, de marketing u otras que se definan) y su propósito. | F14: x | I14: Cumple
B15: 3 | C15: La sección debe indicar explícitamente qué cookies son estrictamente necesarias para el funcionamiento del sitio y que no pueden desactivarse desde el banner. | F15: x | I15: Cumple
B16: 4 | C16: La sección debe informar qué cookies opcionales pueden ser aceptadas o rechazadas por el usuario (funcionales, analíticas, marketing, etc.). | F16: x | I16: Cumple
B17: 5 | C17: La sección debe explicar cómo puede el usuario gestionar sus preferencias de cookies a través del banner inicial y del enlace “Configurar cookies” disponible en el footer. | F17: x | I17: Cumple
B18: 6 | C18: La sección debe indicar el procedimiento para retirar el consentimiento en cualquier momento, incluyendo el acceso directo a la página o componente donde se revocan las cookies opcionales. | F18: x | I18: Cumple
B19: 7 | C19: La sección debe informar si se utilizan cookies de terceros (por ejemplo, herramientas de analítica o publicidad) e identificar a esos terceros o sus categorías. | F19: x | I19: Cumple
B20: 8 | C20: La sección debe indicar la fecha de última actualización de la Política de Cookies para que el usuario sepa desde cuándo son aplicables las condiciones actuales. | F20: x | I20: Cumple

Sheet No-funcionales Cookies
B2: LISTADO DE REQUERIMIENTOS DE COMPRALO | K2: ESTADISTICAS
K3: Requirimientos | L3: =COUNT(B12:D100) -> 30
B4: SI | C4: Marque con una equis (X) si el sistema cumple con la función descrita | K4: Cumplidos | L4: =COUNTIF(F12:F100,"X") -> 30
B5: NO | C5: Marque con una equis (X) si el sistema no cumple con la función descrita | K5: Porcentaje | L5: =PERCENTOF(L4,L3) -> #NAME?
B6: ADI | C6: Marque con una equis (X) si el sistema debe adicionar la función descrita
B7: Observaciones: | D7: Espacio para complementar respuestas
F10: Nivel de cumplimiento | I10: Observaciones
B11: REQUERIMIENTOS NO FUNCIONALES COOKIES | F11: SI | G11: NO | H11: ADI
B13: 1 | C13: La redacción de la Política de Cookies debe utilizar un lenguaje sencillo y comprensible para usuarios no técnicos, evitando jerga legal innecesaria. | F13: x
B14: 2 | C14: La estructura del contenido (títulos, subtítulos, listas) debe facilitar la lectura rápida, permitiendo identificar secciones como “Qué son las cookies”, “Tipos de cookies”, “Cómo gestionar tus preferencias” y “Derechos y más información”. | F14: x
B15: 3 | C15: El texto de la política debe estar disponible al menos en el mismo idioma principal de la tienda y ser fácilmente traducible a otros idiomas (contenido no hardcodeado en el código). | F15: x
B16: 4 | C16: La página de Política de Cookies debe compartir el mismo layout base que el resto del sitio (header, footer, tipografías, colores) para mantener consistencia visual y de navegación. | F16: x
B17: 5 | C17: La sección debe ser totalmente responsiva, presentando el contenido de forma legible tanto en móviles como en pantallas de escritorio sin necesidad de zoom horizontal. | F17: x
B18: 6 | C18: El tamaño de fuente, interlineado y contraste de colores en la Política de Cookies debe cumplir al menos el nivel AA de WCAG 2.1 para asegurar su legibilidad. | F18: x
B19: 7 | C19: Los enlaces dentro de la Política de Cookies (por ejemplo, a la Política de Privacidad o Configurar cookies) deben ser fácilmente reconocibles como tales y accesibles vía teclado. | F19: x
B20: 8 | C20: La sección debe estar optimizada para lectores de pantalla, utilizando encabezados (h1, h2, h3) y listas correctamente anidadas para que la navegación estructurada sea posible. | F20: x
B21: 9 | C21: El tiempo de carga de la página de Política de Cookies no debe diferir de forma significativa del de otras páginas de contenido estático del sitio (sin scripts pesados adicionales). | F21: x
B22: 10 | C22: El contenido de la Política de Cookies debe almacenarse y versionarse de forma que se pueda auditar qué texto estaba vigente en una fecha determinada (por motivos legales/compliance). | F22: x
B23: 11 | C23: Cualquier actualización de la política debe seguir un flujo controlado (revisión y aprobación) antes de ser publicada en producción. | F23: x
B24: 12 | C24: El sistema debe permitir actualizar la fecha de última revisión sin requerir despliegues complejos, idealmente mediante configuración o CMS. | F24: x
... B42: 30 | C42: La sección de descuentos debe respetar las preferencias de cookies y privacidad del usuario, evitando la ejecución de scripts analíticos o de marketing si no se ha otorgado el consentimiento correspondiente. | F42: x

Sheet Funcionales Politicas
A1: mino
B2: LISTADO DE REQUERIMIENTOS DE COMPRALO | K2: ESTADISTICAS
K3: Requirimientos | L3: =COUNT(B12:D75) -> 8
B4: SI | C4: Marque con una equis (X) si el sistema cumple con la función descrita | K4: Cumplidos | L4: =COUNTIF(F12:F75,"X") -> 8
B5: NO | C5: Marque con una equis (X) si el sistema no cumple con la función descrita | K5: Porcentaje | L5: =PERCENTOF(L4,L3) -> #NAME?
B6: ADI | C6: Marque con una equis (X) si el sistema debe adicionar la función descrita
B7: Observaciones: | D7: Espacio para complementar respuestas
F10: Nivel de cumplimiento | I10: Observaciones
B11: REQUERIMIENTOS FUNCIONALES POLITICAS | F11: SI | G11: NO | H11: ADI
B13: 1 | C13: La plataforma debe disponer de una página dedicada de Política de Privacidad accesible desde el footer y desde cualquier punto relevante del sitio. | F13: x | I13: Cumple
B14: 2 | C14: La sección debe indicar claramente el responsable del tratamiento de los datos personales (nombre comercial o razón social y medios de contacto). | F14: x | I14: Cumple
B15: 3 | C15: La sección debe describir de forma explícita los tipos de datos que se recogen (registro, perfil, direcciones, historial de pedidos, navegación, etc.). | F15: x | I15: Cumple
B16: 4 | C16: La sección debe explicar la finalidad y base legal del tratamiento de datos (ejecución del contrato, interés legítimo, consentimiento, obligaciones legales). | F16: x | I16: Cumple
B17: 5 | C17: La sección debe informar los derechos del titular (acceso, rectificación, supresión, oposición, portabilidad, limitación del tratamiento) y el procedimiento para ejercerlos. | F17: x | I17: Cumple
B18: 6 | C18: La sección debe especificar el marco legal aplicable (por ejemplo, Ley 1581 de 2012 y demás normas locales de protección de datos). | F18: x | I18: Cumple
B19: 7 | C19: La sección debe indicar cómo se tratan los datos de pago y financieros (por ejemplo, procesados solo por la pasarela Wompi sin almacenar tarjetas en la plataforma). | F19: x | I19: Cumple
B20: 8 | C20: La sección debe explicar las comunicaciones por email que se envían (transaccionales, de seguridad, marketing opcional) y cómo el usuario puede gestionar sus preferencias. | F20: x | G20: x | I20: No cumple

Sheet No-funcionales Politicas
B2: LISTADO DE REQUERIMIENTOS DE COMPRALO | K2: ESTADISTICAS
K3: Requirimientos | L3: =COUNT(B12:D94) -> 24
B4: SI | C4: Marque con una equis (X) si el sistema cumple con la función descrita | K4: Cumplidos | L4: =COUNTIF(F12:F94,"X") -> 24
B5: NO | C5: Marque con una equis (X) si el sistema no cumple con la función descrita | K5: Porcentaje | L5: =PERCENTOF(L4,L3) -> #NAME?
B6: ADI | C6: Marque con una equis (X) si el sistema debe adicionar la función descrita
B7: Observaciones: | D7: Espacio para complementar respuestas
F10: Nivel de cumplimiento | I10: Observaciones
B11: REQUERIMIENTOS NO FUNCIONALES POLITICAS | F11: SI | G11: NO | H11: ADI
B13: 1 | C13: La página de Política de Privacidad debe ser legible en todo tipo de dispositivo, con tipografía y espaciado que faciliten la lectura de textos largos. | F13: x
B14: 2 | C14: La Política de Privacidad debe estar disponible sin necesidad de iniciar sesión y sin requerir la ejecución de scripts no esenciales. | F14: x
B15: 3 | C15: El contenido de la Política debe ser versionable, conservando fecha de última actualización visible para el usuario. | F15: x
B16: 4 | C16: El texto debe estar redactado en un lenguaje claro y comprensible para personas no expertas en derecho, evitando tecnicismos innecesarios. | F16: x
B17: 5 | C17: La Política de Privacidad debe estar alineada con las prácticas reales de tratamiento de datos implementadas en backend y bases de datos; no debe prometer cosas que el sistema no cumple. | F17: x
B18: 6 | C18: Cualquier cambio relevante en la Política debe poder ser comunicado a los usuarios (por ejemplo, mediante banner o correo) de forma comprobable. | F18: x
B19: 7 | C19: La página debe ser accesible mediante tecnologías de asistencia (lectores de pantalla), con estructura semántica correcta de encabezados y listas. | F19: x
B20: 8 | C20: Los enlaces internos (a contacto, términos, cookies, accesibilidad) deben funcionar de forma consistente y no provocar errores 404. | F20: x
B21: 9 | C21: El rendimiento de la página debe ser óptimo: al ser predominantemente texto, su tiempo de carga debe ser muy bajo incluso en conexiones móviles lentas. | F21: x
